2025-04-02 09:42:52,854 - INFO - [31m[1mWARNING: This is a development server. Do not use it in a production deployment. Use a production WSGI server instead.[0m
 * Running on all addresses (0.0.0.0)
 * Running on http://127.0.0.1:5000
 * Running on http://172.27.0.7:5000
2025-04-02 09:42:52,854 - INFO - [33mPress CTRL+C to quit[0m
2025-04-02 09:42:52,870 - INFO - [31m[1mWARNING: This is a development server. Do not use it in a production deployment. Use a production WSGI server instead.[0m
 * Running on all addresses (0.0.0.0)
 * Running on http://127.0.0.1:5000
 * Running on http://172.27.0.8:5000
2025-04-02 09:42:52,870 - INFO - [33mPress CTRL+C to quit[0m
2025-04-02 09:43:12,109 - INFO - 172.27.0.9 - - [02/Apr/2025 09:43:12] "POST /auth/google/callback HTTP/1.0" 200 -
2025-04-02 09:43:12,165 - ERROR - ç™¼ç”ŸéŒ¯èª¤: argument 'password': 'NoneType' object cannot be converted to 'PyBytes'
Traceback (most recent call last):
  File "/app/services/webhook_service.py", line 48, in handle_bind_email
    if not user or not user.check_password(password):
  File "/app/models.py", line 39, in check_password
    return bcrypt.check_password_hash(self.password_hash, password)
  File "/usr/local/lib/python3.9/site-packages/flask_bcrypt.py", line 225, in check_password_hash
    return hmac.compare_digest(bcrypt.hashpw(password, pw_hash), pw_hash)
TypeError: argument 'password': 'NoneType' object cannot be converted to 'PyBytes'
2025-04-02 09:43:12,169 - INFO - 172.27.0.9 - - [02/Apr/2025 09:43:12] "[35m[1mPOST /bind-email HTTP/1.0[0m" 500 -
2025-04-02 09:43:26,493 - INFO - 172.27.0.9 - - [02/Apr/2025 09:43:26] "GET /users HTTP/1.0" 200 -
2025-04-02 09:43:26,510 - INFO - 172.27.0.9 - - [02/Apr/2025 09:43:26] "GET /get_user_image HTTP/1.0" 200 -
2025-04-02 09:43:34,831 - INFO - 172.27.0.9 - - [02/Apr/2025 09:43:34] "POST /auth/google/callback HTTP/1.0" 200 -
2025-04-02 09:43:34,848 - ERROR - ç™¼ç”ŸéŒ¯èª¤: argument 'password': 'NoneType' object cannot be converted to 'PyBytes'
Traceback (most recent call last):
  File "/app/services/webhook_service.py", line 48, in handle_bind_email
    if not user or not user.check_password(password):
  File "/app/models.py", line 39, in check_password
    return bcrypt.check_password_hash(self.password_hash, password)
  File "/usr/local/lib/python3.9/site-packages/flask_bcrypt.py", line 225, in check_password_hash
    return hmac.compare_digest(bcrypt.hashpw(password, pw_hash), pw_hash)
TypeError: argument 'password': 'NoneType' object cannot be converted to 'PyBytes'
2025-04-02 09:43:34,852 - INFO - 172.27.0.9 - - [02/Apr/2025 09:43:34] "[35m[1mPOST /bind-email HTTP/1.0[0m" 500 -
2025-04-02 09:45:34,141 - INFO - [31m[1mWARNING: This is a development server. Do not use it in a production deployment. Use a production WSGI server instead.[0m
 * Running on all addresses (0.0.0.0)
 * Running on http://127.0.0.1:5000
 * Running on http://172.27.0.8:5000
2025-04-02 09:45:34,142 - INFO - [33mPress CTRL+C to quit[0m
2025-04-02 09:45:34,154 - INFO - [31m[1mWARNING: This is a development server. Do not use it in a production deployment. Use a production WSGI server instead.[0m
 * Running on all addresses (0.0.0.0)
 * Running on http://127.0.0.1:5000
 * Running on http://172.27.0.7:5000
2025-04-02 09:45:34,154 - INFO - [33mPress CTRL+C to quit[0m
2025-04-02 09:45:39,145 - INFO - 172.27.0.9 - - [02/Apr/2025 09:45:39] "GET /users HTTP/1.0" 200 -
2025-04-02 09:45:39,163 - INFO - 172.27.0.9 - - [02/Apr/2025 09:45:39] "GET /get_user_image HTTP/1.0" 200 -
2025-04-02 09:45:49,821 - INFO - 172.27.0.9 - - [02/Apr/2025 09:45:49] "POST /auth/google/callback HTTP/1.0" 200 -
2025-04-02 09:45:49,835 - ERROR - ç™¼ç”ŸéŒ¯èª¤: local variable 'user' referenced before assignment
Traceback (most recent call last):
  File "/app/services/webhook_service.py", line 53, in handle_bind_email
    LineBindingUser.user_id = user.id
UnboundLocalError: local variable 'user' referenced before assignment
2025-04-02 09:45:49,836 - INFO - 172.27.0.9 - - [02/Apr/2025 09:45:49] "[35m[1mPOST /bind-email HTTP/1.0[0m" 500 -
2025-04-02 09:45:59,301 - INFO - 172.27.0.9 - - [02/Apr/2025 09:45:59] "GET /users HTTP/1.0" 200 -
2025-04-02 09:45:59,316 - INFO - 172.27.0.9 - - [02/Apr/2025 09:45:59] "GET /get_user_image HTTP/1.0" 200 -
2025-04-02 09:47:23,386 - INFO - 172.27.0.9 - - [02/Apr/2025 09:47:23] "POST /auth/google/callback HTTP/1.0" 200 -
2025-04-02 09:47:23,404 - ERROR - ç™¼ç”ŸéŒ¯èª¤: local variable 'user' referenced before assignment
Traceback (most recent call last):
  File "/app/services/webhook_service.py", line 53, in handle_bind_email
    LineBindingUser.user_id = user.id
UnboundLocalError: local variable 'user' referenced before assignment
2025-04-02 09:47:23,405 - INFO - 172.27.0.9 - - [02/Apr/2025 09:47:23] "[35m[1mPOST /bind-email HTTP/1.0[0m" 500 -
2025-04-02 09:47:35,389 - INFO - 172.27.0.9 - - [02/Apr/2025 09:47:35] "GET /users HTTP/1.0" 200 -
2025-04-02 09:47:35,393 - INFO - 172.27.0.9 - - [02/Apr/2025 09:47:35] "GET /get_user_image HTTP/1.0" 200 -
2025-04-02 09:47:52,229 - INFO - [31m[1mWARNING: This is a development server. Do not use it in a production deployment. Use a production WSGI server instead.[0m
 * Running on all addresses (0.0.0.0)
 * Running on http://127.0.0.1:5000
 * Running on http://172.27.0.7:5000
2025-04-02 09:47:52,230 - INFO - [33mPress CTRL+C to quit[0m
2025-04-02 09:47:52,317 - INFO - [31m[1mWARNING: This is a development server. Do not use it in a production deployment. Use a production WSGI server instead.[0m
 * Running on all addresses (0.0.0.0)
 * Running on http://127.0.0.1:5000
 * Running on http://172.27.0.8:5000
2025-04-02 09:47:52,318 - INFO - [33mPress CTRL+C to quit[0m
2025-04-02 09:48:25,001 - INFO - [31m[1mWARNING: This is a development server. Do not use it in a production deployment. Use a production WSGI server instead.[0m
 * Running on all addresses (0.0.0.0)
 * Running on http://127.0.0.1:5000
 * Running on http://172.27.0.8:5000
2025-04-02 09:48:25,001 - INFO - [33mPress CTRL+C to quit[0m
2025-04-02 09:48:25,014 - INFO - [31m[1mWARNING: This is a development server. Do not use it in a production deployment. Use a production WSGI server instead.[0m
 * Running on all addresses (0.0.0.0)
 * Running on http://127.0.0.1:5000
 * Running on http://172.27.0.7:5000
2025-04-02 09:48:25,015 - INFO - [33mPress CTRL+C to quit[0m
2025-04-02 09:48:50,862 - INFO - 172.27.0.9 - - [02/Apr/2025 09:48:50] "POST /auth/google/callback HTTP/1.0" 200 -
2025-04-02 09:48:50,883 - ERROR - ç™¼ç”ŸéŒ¯èª¤: local variable 'user' referenced before assignment
Traceback (most recent call last):
  File "/app/services/webhook_service.py", line 53, in handle_bind_email
    LineBindingUser.user_id = user.id
UnboundLocalError: local variable 'user' referenced before assignment
2025-04-02 09:48:50,884 - INFO - 172.27.0.9 - - [02/Apr/2025 09:48:50] "[35m[1mPOST /bind-email HTTP/1.0[0m" 500 -
2025-04-02 09:49:09,394 - INFO - 172.27.0.9 - - [02/Apr/2025 09:49:09] "GET /get_user_image HTTP/1.0" 200 -
2025-04-02 09:49:09,408 - INFO - 172.27.0.9 - - [02/Apr/2025 09:49:09] "GET /users HTTP/1.0" 200 -
2025-04-02 09:49:13,854 - INFO - 172.27.0.9 - - [02/Apr/2025 09:49:13] "GET /users HTTP/1.0" 200 -
2025-04-02 09:49:13,855 - INFO - 172.27.0.9 - - [02/Apr/2025 09:49:13] "[36mGET /get_user_image HTTP/1.0[0m" 304 -
2025-04-02 09:49:18,413 - INFO - 172.27.0.9 - - [02/Apr/2025 09:49:18] "[36mGET /get_user_image HTTP/1.0[0m" 304 -
2025-04-02 09:50:11,798 - INFO - 172.27.0.9 - - [02/Apr/2025 09:50:11] "POST /auth/google/callback HTTP/1.0" 200 -
2025-04-02 09:50:24,342 - ERROR - ç™¼ç”ŸéŒ¯èª¤: local variable 'user' referenced before assignment
Traceback (most recent call last):
  File "/app/services/webhook_service.py", line 53, in handle_bind_email
    LineBindingUser.user_id = user.id
UnboundLocalError: local variable 'user' referenced before assignment
2025-04-02 09:50:24,344 - INFO - 172.27.0.9 - - [02/Apr/2025 09:50:24] "[35m[1mPOST /bind-email HTTP/1.0[0m" 500 -
2025-04-02 09:51:10,692 - INFO - 172.27.0.9 - - [02/Apr/2025 09:51:10] "GET /users HTTP/1.0" 200 -
2025-04-02 09:51:10,715 - INFO - 172.27.0.9 - - [02/Apr/2025 09:51:10] "GET /get_user_image HTTP/1.0" 200 -
2025-04-02 09:51:27,286 - INFO - 172.27.0.9 - - [02/Apr/2025 09:51:27] "POST /auth/google/callback HTTP/1.0" 200 -
2025-04-02 09:51:47,232 - ERROR - ç™¼ç”ŸéŒ¯èª¤: local variable 'user' referenced before assignment
Traceback (most recent call last):
  File "/app/services/webhook_service.py", line 53, in handle_bind_email
    LineBindingUser.user_id = user.id
UnboundLocalError: local variable 'user' referenced before assignment
2025-04-02 09:51:47,233 - INFO - 172.27.0.9 - - [02/Apr/2025 09:51:47] "[35m[1mPOST /bind-email HTTP/1.0[0m" 500 -
2025-04-02 09:52:25,393 - INFO - 172.27.0.9 - - [02/Apr/2025 09:52:25] "GET /get_user_image HTTP/1.0" 200 -
2025-04-02 09:52:25,496 - INFO - 172.27.0.9 - - [02/Apr/2025 09:52:25] "GET /users HTTP/1.0" 200 -
2025-04-02 09:54:11,550 - INFO - [31m[1mWARNING: This is a development server. Do not use it in a production deployment. Use a production WSGI server instead.[0m
 * Running on all addresses (0.0.0.0)
 * Running on http://127.0.0.1:5000
 * Running on http://172.27.0.7:5000
2025-04-02 09:54:11,550 - INFO - [33mPress CTRL+C to quit[0m
2025-04-02 09:54:11,627 - INFO - [31m[1mWARNING: This is a development server. Do not use it in a production deployment. Use a production WSGI server instead.[0m
 * Running on all addresses (0.0.0.0)
 * Running on http://127.0.0.1:5000
 * Running on http://172.27.0.8:5000
2025-04-02 09:54:11,628 - INFO - [33mPress CTRL+C to quit[0m
2025-04-02 09:59:13,057 - INFO - 172.27.0.9 - - [02/Apr/2025 09:59:13] "POST /auth/google/callback HTTP/1.0" 200 -
2025-04-02 09:59:13,069 - ERROR - ç™¼ç”ŸéŒ¯èª¤: local variable 'user' referenced before assignment
Traceback (most recent call last):
  File "/app/services/webhook_service.py", line 53, in handle_bind_email
    LineBindingUser.user_id = user.id
UnboundLocalError: local variable 'user' referenced before assignment
2025-04-02 09:59:13,071 - INFO - 172.27.0.9 - - [02/Apr/2025 09:59:13] "[35m[1mPOST /bind-email HTTP/1.0[0m" 500 -
2025-04-02 09:59:32,884 - INFO - 172.27.0.9 - - [02/Apr/2025 09:59:32] "POST /auth/google/callback HTTP/1.0" 200 -
2025-04-02 09:59:41,233 - ERROR - ç™¼ç”ŸéŒ¯èª¤: local variable 'user' referenced before assignment
Traceback (most recent call last):
  File "/app/services/webhook_service.py", line 53, in handle_bind_email
    LineBindingUser.user_id = user.id
UnboundLocalError: local variable 'user' referenced before assignment
2025-04-02 09:59:41,234 - INFO - 172.27.0.9 - - [02/Apr/2025 09:59:41] "[35m[1mPOST /bind-email HTTP/1.0[0m" 500 -
2025-04-02 10:01:23,148 - INFO - [31m[1mWARNING: This is a development server. Do not use it in a production deployment. Use a production WSGI server instead.[0m
 * Running on all addresses (0.0.0.0)
 * Running on http://127.0.0.1:5000
 * Running on http://172.27.0.8:5000
2025-04-02 10:01:23,149 - INFO - [33mPress CTRL+C to quit[0m
2025-04-02 10:01:23,176 - INFO - [31m[1mWARNING: This is a development server. Do not use it in a production deployment. Use a production WSGI server instead.[0m
 * Running on all addresses (0.0.0.0)
 * Running on http://127.0.0.1:5000
 * Running on http://172.27.0.7:5000
2025-04-02 10:01:23,177 - INFO - [33mPress CTRL+C to quit[0m
2025-04-02 10:01:50,405 - INFO - 172.27.0.9 - - [02/Apr/2025 10:01:50] "GET /users HTTP/1.0" 200 -
2025-04-02 10:01:50,417 - INFO - 172.27.0.9 - - [02/Apr/2025 10:01:50] "GET /get_user_image HTTP/1.0" 200 -
2025-04-02 10:02:11,495 - INFO - 172.27.0.9 - - [02/Apr/2025 10:02:11] "POST /auth/google/callback HTTP/1.0" 200 -
2025-04-02 10:02:11,512 - ERROR - ç™¼ç”ŸéŒ¯èª¤: local variable 'user' referenced before assignment
Traceback (most recent call last):
  File "/app/services/webhook_service.py", line 53, in handle_bind_email
    LineBindingUser.user_id = user.id
UnboundLocalError: local variable 'user' referenced before assignment
2025-04-02 10:02:11,514 - INFO - 172.27.0.9 - - [02/Apr/2025 10:02:11] "[35m[1mPOST /bind-email HTTP/1.0[0m" 500 -
2025-04-02 10:02:58,521 - INFO - 172.27.0.9 - - [02/Apr/2025 10:02:58] "GET /get_user_image HTTP/1.0" 200 -
2025-04-02 10:02:58,532 - INFO - 172.27.0.9 - - [02/Apr/2025 10:02:58] "GET /users HTTP/1.0" 200 -
2025-04-02 10:03:07,169 - INFO - [31m[1mWARNING: This is a development server. Do not use it in a production deployment. Use a production WSGI server instead.[0m
 * Running on all addresses (0.0.0.0)
 * Running on http://127.0.0.1:5000
 * Running on http://172.27.0.8:5000
2025-04-02 10:03:07,169 - INFO - [33mPress CTRL+C to quit[0m
2025-04-02 10:03:07,329 - INFO - [31m[1mWARNING: This is a development server. Do not use it in a production deployment. Use a production WSGI server instead.[0m
 * Running on all addresses (0.0.0.0)
 * Running on http://127.0.0.1:5000
 * Running on http://172.27.0.7:5000
2025-04-02 10:03:07,330 - INFO - [33mPress CTRL+C to quit[0m
2025-04-02 10:03:13,677 - INFO - 172.27.0.9 - - [02/Apr/2025 10:03:13] "POST /auth/google/callback HTTP/1.0" 200 -
2025-04-02 10:03:13,716 - INFO - 172.27.0.9 - - [02/Apr/2025 10:03:13] "GET /users HTTP/1.0" 200 -
2025-04-02 10:03:13,759 - INFO - 172.27.0.9 - - [02/Apr/2025 10:03:13] "GET /get_user_image HTTP/1.0" 200 -
2025-04-02 10:03:30,614 - INFO - 172.27.0.9 - - [02/Apr/2025 10:03:30] "POST /auth/google/callback HTTP/1.0" 200 -
2025-04-02 10:03:51,650 - ERROR - ç™¼ç”ŸéŒ¯èª¤: local variable 'user' referenced before assignment
Traceback (most recent call last):
  File "/app/services/webhook_service.py", line 53, in handle_bind_email
    LineBindingUser.user_id = user.id
UnboundLocalError: local variable 'user' referenced before assignment
2025-04-02 10:03:51,652 - INFO - 172.27.0.9 - - [02/Apr/2025 10:03:51] "[35m[1mPOST /bind-email HTTP/1.0[0m" 500 -
2025-04-02 10:05:53,149 - INFO - [31m[1mWARNING: This is a development server. Do not use it in a production deployment. Use a production WSGI server instead.[0m
 * Running on all addresses (0.0.0.0)
 * Running on http://127.0.0.1:5000
 * Running on http://172.27.0.8:5000
2025-04-02 10:05:53,151 - INFO - [31m[1mWARNING: This is a development server. Do not use it in a production deployment. Use a production WSGI server instead.[0m
 * Running on all addresses (0.0.0.0)
 * Running on http://127.0.0.1:5000
 * Running on http://172.27.0.7:5000
2025-04-02 10:05:53,151 - INFO - [33mPress CTRL+C to quit[0m
2025-04-02 10:05:53,151 - INFO - [33mPress CTRL+C to quit[0m
2025-04-02 10:06:21,234 - INFO - 172.27.0.9 - - [02/Apr/2025 10:06:21] "GET /users HTTP/1.0" 200 -
2025-04-02 10:06:21,251 - INFO - 172.27.0.9 - - [02/Apr/2025 10:06:21] "GET /get_user_image HTTP/1.0" 200 -
2025-04-02 10:06:28,751 - INFO - 172.27.0.9 - - [02/Apr/2025 10:06:28] "POST /auth/google/callback HTTP/1.0" 200 -
2025-04-02 10:06:32,521 - INFO - 172.27.0.9 - - [02/Apr/2025 10:06:32] "POST /bind-email HTTP/1.0" 200 -
2025-04-02 10:06:32,550 - INFO - 172.27.0.9 - - [02/Apr/2025 10:06:32] "GET /users HTTP/1.0" 200 -
2025-04-02 10:06:32,569 - INFO - 172.27.0.9 - - [02/Apr/2025 10:06:32] "GET /get_user_image HTTP/1.0" 200 -
2025-04-02 11:23:56,038 - INFO - 172.27.0.9 - - [02/Apr/2025 11:23:56] "POST /auth/google/callback HTTP/1.0" 200 -
2025-04-02 11:23:56,085 - INFO - 172.27.0.9 - - [02/Apr/2025 11:23:56] "GET /get_user_image HTTP/1.0" 200 -
2025-04-02 11:23:56,097 - INFO - 172.27.0.9 - - [02/Apr/2025 11:23:56] "GET /users HTTP/1.0" 200 -
2025-04-02 11:25:25,220 - INFO - [31m[1mWARNING: This is a development server. Do not use it in a production deployment. Use a production WSGI server instead.[0m
 * Running on all addresses (0.0.0.0)
 * Running on http://127.0.0.1:5000
 * Running on http://172.27.0.8:5000
2025-04-02 11:25:25,221 - INFO - [33mPress CTRL+C to quit[0m
2025-04-02 11:25:25,310 - INFO - [31m[1mWARNING: This is a development server. Do not use it in a production deployment. Use a production WSGI server instead.[0m
 * Running on all addresses (0.0.0.0)
 * Running on http://127.0.0.1:5000
 * Running on http://172.27.0.7:5000
2025-04-02 11:25:25,310 - INFO - [33mPress CTRL+C to quit[0m
2025-04-02 11:27:29,468 - INFO - 172.27.0.9 - - [02/Apr/2025 11:27:29] "POST /auth/google/callback HTTP/1.0" 200 -
2025-04-02 11:27:32,454 - ERROR - {'message': 'Email sent successfully'}
2025-04-02 11:27:32,456 - INFO - 172.27.0.9 - - [02/Apr/2025 11:27:32] "POST /bind-email HTTP/1.0" 200 -
2025-04-02 11:27:32,492 - INFO - 172.27.0.9 - - [02/Apr/2025 11:27:32] "GET /users HTTP/1.0" 200 -
2025-04-02 11:27:32,508 - INFO - 172.27.0.9 - - [02/Apr/2025 11:27:32] "GET /get_user_image HTTP/1.0" 200 -
2025-04-02 11:29:35,059 - ERROR - ç™¼ç”ŸéŒ¯èª¤: argument 'salt': 'NoneType' object cannot be converted to 'PyBytes'
Traceback (most recent call last):
  File "/app/services/webhook_service.py", line 52, in handle_bind_email
    if password and not user.check_password(password):
  File "/app/models.py", line 39, in check_password
    return bcrypt.check_password_hash(self.password_hash, password)
  File "/usr/local/lib/python3.9/site-packages/flask_bcrypt.py", line 225, in check_password_hash
    return hmac.compare_digest(bcrypt.hashpw(password, pw_hash), pw_hash)
TypeError: argument 'salt': 'NoneType' object cannot be converted to 'PyBytes'
2025-04-02 11:29:35,063 - INFO - 172.27.0.9 - - [02/Apr/2025 11:29:35] "[35m[1mPOST /bind-email HTTP/1.0[0m" 500 -
2025-04-02 11:45:35,372 - INFO - [31m[1mWARNING: This is a development server. Do not use it in a production deployment. Use a production WSGI server instead.[0m
 * Running on all addresses (0.0.0.0)
 * Running on http://127.0.0.1:5000
 * Running on http://172.27.0.7:5000
2025-04-02 11:45:35,373 - INFO - [33mPress CTRL+C to quit[0m
2025-04-02 11:45:35,425 - INFO - [31m[1mWARNING: This is a development server. Do not use it in a production deployment. Use a production WSGI server instead.[0m
 * Running on all addresses (0.0.0.0)
 * Running on http://127.0.0.1:5000
 * Running on http://172.27.0.8:5000
2025-04-02 11:45:35,425 - INFO - [33mPress CTRL+C to quit[0m
2025-04-02 12:38:16,521 - INFO - [31m[1mWARNING: This is a development server. Do not use it in a production deployment. Use a production WSGI server instead.[0m
 * Running on all addresses (0.0.0.0)
 * Running on http://127.0.0.1:5000
 * Running on http://172.27.0.7:5000
2025-04-02 12:38:16,521 - INFO - [33mPress CTRL+C to quit[0m
2025-04-02 12:38:16,604 - INFO - [31m[1mWARNING: This is a development server. Do not use it in a production deployment. Use a production WSGI server instead.[0m
 * Running on all addresses (0.0.0.0)
 * Running on http://127.0.0.1:5000
 * Running on http://172.27.0.8:5000
2025-04-02 12:38:16,604 - INFO - [33mPress CTRL+C to quit[0m
2025-04-02 12:39:47,457 - ERROR - ç™¼ç”ŸéŒ¯èª¤: argument 'salt': 'NoneType' object cannot be converted to 'PyBytes'
Traceback (most recent call last):
  File "/app/services/webhook_service.py", line 72, in handle_bind_email
    if password and not user.check_password(password):
  File "/app/models.py", line 39, in check_password
    return bcrypt.check_password_hash(self.password_hash, password)
  File "/usr/local/lib/python3.9/site-packages/flask_bcrypt.py", line 225, in check_password_hash
    return hmac.compare_digest(bcrypt.hashpw(password, pw_hash), pw_hash)
TypeError: argument 'salt': 'NoneType' object cannot be converted to 'PyBytes'
2025-04-02 12:39:47,461 - INFO - 172.27.0.9 - - [02/Apr/2025 12:39:47] "[35m[1mPOST /bind-email HTTP/1.0[0m" 500 -
2025-04-02 12:47:06,488 - INFO - 172.27.0.9 - - [02/Apr/2025 12:47:06] "[33mGET /.git/config HTTP/1.0[0m" 404 -
2025-04-02 12:47:09,864 - INFO - 172.27.0.9 - - [02/Apr/2025 12:47:09] "[33mGET /.env HTTP/1.0[0m" 404 -
2025-04-02 12:51:28,673 - INFO - [31m[1mWARNING: This is a development server. Do not use it in a production deployment. Use a production WSGI server instead.[0m
 * Running on all addresses (0.0.0.0)
 * Running on http://127.0.0.1:5000
 * Running on http://172.27.0.8:5000
2025-04-02 12:51:28,673 - INFO - [33mPress CTRL+C to quit[0m
2025-04-02 12:51:28,678 - INFO - [31m[1mWARNING: This is a development server. Do not use it in a production deployment. Use a production WSGI server instead.[0m
 * Running on all addresses (0.0.0.0)
 * Running on http://127.0.0.1:5000
 * Running on http://172.27.0.7:5000
2025-04-02 12:51:28,678 - INFO - [33mPress CTRL+C to quit[0m
2025-04-02 13:06:43,677 - ERROR - Google Token é©—è­‰å¤±æ•—: Expecting value: line 1 column 1 (char 0)
Traceback (most recent call last):
  File "/usr/local/lib/python3.9/site-packages/requests/models.py", line 974, in json
    return complexjson.loads(self.text, **kwargs)
  File "/usr/local/lib/python3.9/json/__init__.py", line 346, in loads
    return _default_decoder.decode(s)
  File "/usr/local/lib/python3.9/json/decoder.py", line 337, in decode
    obj, end = self.raw_decode(s, idx=_w(s, 0).end())
  File "/usr/local/lib/python3.9/json/decoder.py", line 355, in raw_decode
    raise JSONDecodeError("Expecting value", s, err.value) from None
json.decoder.JSONDecodeError: Expecting value: line 1 column 1 (char 0)

During handling of the above exception, another exception occurred:

Traceback (most recent call last):
  File "/app/services/webhook_service.py", line 30, in verify_google_token
    return response.json()
  File "/usr/local/lib/python3.9/site-packages/requests/models.py", line 978, in json
    raise RequestsJSONDecodeError(e.msg, e.doc, e.pos)
requests.exceptions.JSONDecodeError: Expecting value: line 1 column 1 (char 0)
2025-04-02 13:06:43,684 - INFO - 172.27.0.9 - - [02/Apr/2025 13:06:43] "[31m[1mPOST /bind-email HTTP/1.0[0m" 400 -
2025-04-02 13:14:07,662 - INFO - [31m[1mWARNING: This is a development server. Do not use it in a production deployment. Use a production WSGI server instead.[0m
 * Running on all addresses (0.0.0.0)
 * Running on http://127.0.0.1:5000
 * Running on http://172.27.0.7:5000
2025-04-02 13:14:07,662 - INFO - [33mPress CTRL+C to quit[0m
2025-04-02 13:14:07,693 - INFO - [31m[1mWARNING: This is a development server. Do not use it in a production deployment. Use a production WSGI server instead.[0m
 * Running on all addresses (0.0.0.0)
 * Running on http://127.0.0.1:5000
 * Running on http://172.27.0.8:5000
2025-04-02 13:14:07,693 - INFO - [33mPress CTRL+C to quit[0m
2025-04-03 01:14:42,479 - ERROR - Google Token é©—è­‰å¤±æ•—: Expecting value: line 1 column 1 (char 0)
Traceback (most recent call last):
  File "/usr/local/lib/python3.9/site-packages/requests/models.py", line 974, in json
    return complexjson.loads(self.text, **kwargs)
  File "/usr/local/lib/python3.9/json/__init__.py", line 346, in loads
    return _default_decoder.decode(s)
  File "/usr/local/lib/python3.9/json/decoder.py", line 337, in decode
    obj, end = self.raw_decode(s, idx=_w(s, 0).end())
  File "/usr/local/lib/python3.9/json/decoder.py", line 355, in raw_decode
    raise JSONDecodeError("Expecting value", s, err.value) from None
json.decoder.JSONDecodeError: Expecting value: line 1 column 1 (char 0)

During handling of the above exception, another exception occurred:

Traceback (most recent call last):
  File "/app/services/webhook_service.py", line 30, in verify_google_token
    return response.json()
  File "/usr/local/lib/python3.9/site-packages/requests/models.py", line 978, in json
    raise RequestsJSONDecodeError(e.msg, e.doc, e.pos)
requests.exceptions.JSONDecodeError: Expecting value: line 1 column 1 (char 0)
2025-04-03 01:14:42,486 - INFO - 172.27.0.9 - - [03/Apr/2025 01:14:42] "[31m[1mPOST /bind-email HTTP/1.0[0m" 400 -
2025-04-03 01:15:00,553 - ERROR - Google Token é©—è­‰å¤±æ•—: Expecting value: line 1 column 1 (char 0)
Traceback (most recent call last):
  File "/usr/local/lib/python3.9/site-packages/requests/models.py", line 974, in json
    return complexjson.loads(self.text, **kwargs)
  File "/usr/local/lib/python3.9/json/__init__.py", line 346, in loads
    return _default_decoder.decode(s)
  File "/usr/local/lib/python3.9/json/decoder.py", line 337, in decode
    obj, end = self.raw_decode(s, idx=_w(s, 0).end())
  File "/usr/local/lib/python3.9/json/decoder.py", line 355, in raw_decode
    raise JSONDecodeError("Expecting value", s, err.value) from None
json.decoder.JSONDecodeError: Expecting value: line 1 column 1 (char 0)

During handling of the above exception, another exception occurred:

Traceback (most recent call last):
  File "/app/services/webhook_service.py", line 30, in verify_google_token
    return response.json()
  File "/usr/local/lib/python3.9/site-packages/requests/models.py", line 978, in json
    raise RequestsJSONDecodeError(e.msg, e.doc, e.pos)
requests.exceptions.JSONDecodeError: Expecting value: line 1 column 1 (char 0)
2025-04-03 01:15:00,560 - INFO - 172.27.0.9 - - [03/Apr/2025 01:15:00] "[31m[1mPOST /bind-email HTTP/1.0[0m" 400 -
2025-04-03 01:21:42,188 - INFO - [31m[1mWARNING: This is a development server. Do not use it in a production deployment. Use a production WSGI server instead.[0m
 * Running on all addresses (0.0.0.0)
 * Running on http://127.0.0.1:5000
 * Running on http://172.27.0.8:5000
2025-04-03 01:21:42,188 - INFO - [33mPress CTRL+C to quit[0m
2025-04-03 01:21:42,211 - INFO - [31m[1mWARNING: This is a development server. Do not use it in a production deployment. Use a production WSGI server instead.[0m
 * Running on all addresses (0.0.0.0)
 * Running on http://127.0.0.1:5000
 * Running on http://172.27.0.7:5000
2025-04-03 01:21:42,211 - INFO - [33mPress CTRL+C to quit[0m
2025-04-03 01:24:24,933 - INFO - 172.27.0.9 - - [03/Apr/2025 01:24:24] "POST /bind-email HTTP/1.0" 200 -
2025-04-03 01:24:24,993 - INFO - 172.27.0.9 - - [03/Apr/2025 01:24:24] "[31m[1mGET /get_user_image HTTP/1.0[0m" 401 -
2025-04-03 01:25:03,460 - INFO - 172.27.0.9 - - [03/Apr/2025 01:25:03] "[31m[1mGET /get_user_image HTTP/1.0[0m" 401 -
2025-04-03 01:25:46,831 - INFO - 172.27.0.9 - - [03/Apr/2025 01:25:46] "POST /auth/google/callback HTTP/1.0" 200 -
2025-04-03 01:25:46,905 - INFO - 172.27.0.9 - - [03/Apr/2025 01:25:46] "GET /get_user_image HTTP/1.0" 200 -
2025-04-03 01:25:46,923 - INFO - 172.27.0.9 - - [03/Apr/2025 01:25:46] "GET /users HTTP/1.0" 200 -
2025-04-03 01:26:42,538 - INFO - 172.27.0.9 - - [03/Apr/2025 01:26:42] "[36mGET /get_user_image HTTP/1.0[0m" 304 -
2025-04-03 01:27:51,317 - ERROR - ç™¼ç”ŸéŒ¯èª¤: UPDATE statement on table 'line_binding_user' expected to update 1 row(s); 2 were matched.
Traceback (most recent call last):
  File "/app/services/webhook_service.py", line 90, in handle_bind_email
    db.session.commit()
  File "/usr/local/lib/python3.9/site-packages/sqlalchemy/orm/scoping.py", line 599, in commit
    return self._proxied.commit()
  File "/usr/local/lib/python3.9/site-packages/sqlalchemy/orm/session.py", line 2032, in commit
    trans.commit(_to_root=True)
  File "<string>", line 2, in commit
  File "/usr/local/lib/python3.9/site-packages/sqlalchemy/orm/state_changes.py", line 139, in _go
    ret_value = fn(self, *arg, **kw)
  File "/usr/local/lib/python3.9/site-packages/sqlalchemy/orm/session.py", line 1313, in commit
    self._prepare_impl()
  File "<string>", line 2, in _prepare_impl
  File "/usr/local/lib/python3.9/site-packages/sqlalchemy/orm/state_changes.py", line 139, in _go
    ret_value = fn(self, *arg, **kw)
  File "/usr/local/lib/python3.9/site-packages/sqlalchemy/orm/session.py", line 1288, in _prepare_impl
    self.session.flush()
  File "/usr/local/lib/python3.9/site-packages/sqlalchemy/orm/session.py", line 4353, in flush
    self._flush(objects)
  File "/usr/local/lib/python3.9/site-packages/sqlalchemy/orm/session.py", line 4489, in _flush
    transaction.rollback(_capture_exception=True)
  File "/usr/local/lib/python3.9/site-packages/sqlalchemy/util/langhelpers.py", line 146, in __exit__
    raise exc_value.with_traceback(exc_tb)
  File "/usr/local/lib/python3.9/site-packages/sqlalchemy/orm/session.py", line 4449, in _flush
    flush_context.execute()
  File "/usr/local/lib/python3.9/site-packages/sqlalchemy/orm/unitofwork.py", line 466, in execute
    rec.execute(self)
  File "/usr/local/lib/python3.9/site-packages/sqlalchemy/orm/unitofwork.py", line 642, in execute
    util.preloaded.orm_persistence.save_obj(
  File "/usr/local/lib/python3.9/site-packages/sqlalchemy/orm/persistence.py", line 85, in save_obj
    _emit_update_statements(
  File "/usr/local/lib/python3.9/site-packages/sqlalchemy/orm/persistence.py", line 948, in _emit_update_statements
    raise orm_exc.StaleDataError(
sqlalchemy.orm.exc.StaleDataError: UPDATE statement on table 'line_binding_user' expected to update 1 row(s); 2 were matched.
2025-04-03 01:27:51,329 - INFO - 172.27.0.9 - - [03/Apr/2025 01:27:51] "[35m[1mPOST /bind-email HTTP/1.0[0m" 500 -
2025-04-03 01:29:25,616 - ERROR - ç™¼ç”ŸéŒ¯èª¤: UPDATE statement on table 'line_binding_user' expected to update 1 row(s); 2 were matched.
Traceback (most recent call last):
  File "/app/services/webhook_service.py", line 90, in handle_bind_email
    db.session.commit()
  File "/usr/local/lib/python3.9/site-packages/sqlalchemy/orm/scoping.py", line 599, in commit
    return self._proxied.commit()
  File "/usr/local/lib/python3.9/site-packages/sqlalchemy/orm/session.py", line 2032, in commit
    trans.commit(_to_root=True)
  File "<string>", line 2, in commit
  File "/usr/local/lib/python3.9/site-packages/sqlalchemy/orm/state_changes.py", line 139, in _go
    ret_value = fn(self, *arg, **kw)
  File "/usr/local/lib/python3.9/site-packages/sqlalchemy/orm/session.py", line 1313, in commit
    self._prepare_impl()
  File "<string>", line 2, in _prepare_impl
  File "/usr/local/lib/python3.9/site-packages/sqlalchemy/orm/state_changes.py", line 139, in _go
    ret_value = fn(self, *arg, **kw)
  File "/usr/local/lib/python3.9/site-packages/sqlalchemy/orm/session.py", line 1288, in _prepare_impl
    self.session.flush()
  File "/usr/local/lib/python3.9/site-packages/sqlalchemy/orm/session.py", line 4353, in flush
    self._flush(objects)
  File "/usr/local/lib/python3.9/site-packages/sqlalchemy/orm/session.py", line 4489, in _flush
    transaction.rollback(_capture_exception=True)
  File "/usr/local/lib/python3.9/site-packages/sqlalchemy/util/langhelpers.py", line 146, in __exit__
    raise exc_value.with_traceback(exc_tb)
  File "/usr/local/lib/python3.9/site-packages/sqlalchemy/orm/session.py", line 4449, in _flush
    flush_context.execute()
  File "/usr/local/lib/python3.9/site-packages/sqlalchemy/orm/unitofwork.py", line 466, in execute
    rec.execute(self)
  File "/usr/local/lib/python3.9/site-packages/sqlalchemy/orm/unitofwork.py", line 642, in execute
    util.preloaded.orm_persistence.save_obj(
  File "/usr/local/lib/python3.9/site-packages/sqlalchemy/orm/persistence.py", line 85, in save_obj
    _emit_update_statements(
  File "/usr/local/lib/python3.9/site-packages/sqlalchemy/orm/persistence.py", line 948, in _emit_update_statements
    raise orm_exc.StaleDataError(
sqlalchemy.orm.exc.StaleDataError: UPDATE statement on table 'line_binding_user' expected to update 1 row(s); 2 were matched.
2025-04-03 01:29:25,630 - INFO - 172.27.0.9 - - [03/Apr/2025 01:29:25] "[35m[1mPOST /bind-email HTTP/1.0[0m" 500 -
2025-04-03 01:32:23,748 - INFO - 172.27.0.9 - - [03/Apr/2025 01:32:23] "POST /bind-email HTTP/1.0" 200 -
2025-04-03 01:32:23,803 - INFO - 172.27.0.9 - - [03/Apr/2025 01:32:23] "[36mGET /get_user_image HTTP/1.0[0m" 304 -
2025-04-03 01:32:29,866 - INFO - 172.27.0.9 - - [03/Apr/2025 01:32:29] "POST /auth/google/callback HTTP/1.0" 200 -
2025-04-03 01:32:29,913 - INFO - 172.27.0.9 - - [03/Apr/2025 01:32:29] "GET /users HTTP/1.0" 200 -
2025-04-03 01:32:29,913 - INFO - 172.27.0.9 - - [03/Apr/2025 01:32:29] "GET /get_user_image HTTP/1.0" 200 -
2025-04-03 01:32:33,911 - INFO - 172.27.0.9 - - [03/Apr/2025 01:32:33] "GET /users HTTP/1.0" 200 -
2025-04-03 01:32:33,912 - INFO - 172.27.0.9 - - [03/Apr/2025 01:32:33] "[36mGET /get_user_image HTTP/1.0[0m" 304 -
2025-04-03 01:32:49,047 - ERROR - ç™¼ç”ŸéŒ¯èª¤: UPDATE statement on table 'line_binding_user' expected to update 1 row(s); 2 were matched.
Traceback (most recent call last):
  File "/app/services/webhook_service.py", line 90, in handle_bind_email
    db.session.commit()
  File "/usr/local/lib/python3.9/site-packages/sqlalchemy/orm/scoping.py", line 599, in commit
    return self._proxied.commit()
  File "/usr/local/lib/python3.9/site-packages/sqlalchemy/orm/session.py", line 2032, in commit
    trans.commit(_to_root=True)
  File "<string>", line 2, in commit
  File "/usr/local/lib/python3.9/site-packages/sqlalchemy/orm/state_changes.py", line 139, in _go
    ret_value = fn(self, *arg, **kw)
  File "/usr/local/lib/python3.9/site-packages/sqlalchemy/orm/session.py", line 1313, in commit
    self._prepare_impl()
  File "<string>", line 2, in _prepare_impl
  File "/usr/local/lib/python3.9/site-packages/sqlalchemy/orm/state_changes.py", line 139, in _go
    ret_value = fn(self, *arg, **kw)
  File "/usr/local/lib/python3.9/site-packages/sqlalchemy/orm/session.py", line 1288, in _prepare_impl
    self.session.flush()
  File "/usr/local/lib/python3.9/site-packages/sqlalchemy/orm/session.py", line 4353, in flush
    self._flush(objects)
  File "/usr/local/lib/python3.9/site-packages/sqlalchemy/orm/session.py", line 4489, in _flush
    transaction.rollback(_capture_exception=True)
  File "/usr/local/lib/python3.9/site-packages/sqlalchemy/util/langhelpers.py", line 146, in __exit__
    raise exc_value.with_traceback(exc_tb)
  File "/usr/local/lib/python3.9/site-packages/sqlalchemy/orm/session.py", line 4449, in _flush
    flush_context.execute()
  File "/usr/local/lib/python3.9/site-packages/sqlalchemy/orm/unitofwork.py", line 466, in execute
    rec.execute(self)
  File "/usr/local/lib/python3.9/site-packages/sqlalchemy/orm/unitofwork.py", line 642, in execute
    util.preloaded.orm_persistence.save_obj(
  File "/usr/local/lib/python3.9/site-packages/sqlalchemy/orm/persistence.py", line 85, in save_obj
    _emit_update_statements(
  File "/usr/local/lib/python3.9/site-packages/sqlalchemy/orm/persistence.py", line 948, in _emit_update_statements
    raise orm_exc.StaleDataError(
sqlalchemy.orm.exc.StaleDataError: UPDATE statement on table 'line_binding_user' expected to update 1 row(s); 2 were matched.
2025-04-03 01:32:49,049 - INFO - 172.27.0.9 - - [03/Apr/2025 01:32:49] "[35m[1mPOST /bind-email HTTP/1.0[0m" 500 -
2025-04-03 01:33:22,668 - ERROR - ç™¼ç”ŸéŒ¯èª¤: UPDATE statement on table 'line_binding_user' expected to update 1 row(s); 2 were matched.
Traceback (most recent call last):
  File "/app/services/webhook_service.py", line 90, in handle_bind_email
    db.session.commit()
  File "/usr/local/lib/python3.9/site-packages/sqlalchemy/orm/scoping.py", line 599, in commit
    return self._proxied.commit()
  File "/usr/local/lib/python3.9/site-packages/sqlalchemy/orm/session.py", line 2032, in commit
    trans.commit(_to_root=True)
  File "<string>", line 2, in commit
  File "/usr/local/lib/python3.9/site-packages/sqlalchemy/orm/state_changes.py", line 139, in _go
    ret_value = fn(self, *arg, **kw)
  File "/usr/local/lib/python3.9/site-packages/sqlalchemy/orm/session.py", line 1313, in commit
    self._prepare_impl()
  File "<string>", line 2, in _prepare_impl
  File "/usr/local/lib/python3.9/site-packages/sqlalchemy/orm/state_changes.py", line 139, in _go
    ret_value = fn(self, *arg, **kw)
  File "/usr/local/lib/python3.9/site-packages/sqlalchemy/orm/session.py", line 1288, in _prepare_impl
    self.session.flush()
  File "/usr/local/lib/python3.9/site-packages/sqlalchemy/orm/session.py", line 4353, in flush
    self._flush(objects)
  File "/usr/local/lib/python3.9/site-packages/sqlalchemy/orm/session.py", line 4489, in _flush
    transaction.rollback(_capture_exception=True)
  File "/usr/local/lib/python3.9/site-packages/sqlalchemy/util/langhelpers.py", line 146, in __exit__
    raise exc_value.with_traceback(exc_tb)
  File "/usr/local/lib/python3.9/site-packages/sqlalchemy/orm/session.py", line 4449, in _flush
    flush_context.execute()
  File "/usr/local/lib/python3.9/site-packages/sqlalchemy/orm/unitofwork.py", line 466, in execute
    rec.execute(self)
  File "/usr/local/lib/python3.9/site-packages/sqlalchemy/orm/unitofwork.py", line 642, in execute
    util.preloaded.orm_persistence.save_obj(
  File "/usr/local/lib/python3.9/site-packages/sqlalchemy/orm/persistence.py", line 85, in save_obj
    _emit_update_statements(
  File "/usr/local/lib/python3.9/site-packages/sqlalchemy/orm/persistence.py", line 948, in _emit_update_statements
    raise orm_exc.StaleDataError(
sqlalchemy.orm.exc.StaleDataError: UPDATE statement on table 'line_binding_user' expected to update 1 row(s); 2 were matched.
2025-04-03 01:33:22,670 - INFO - 172.27.0.9 - - [03/Apr/2025 01:33:22] "[35m[1mPOST /bind-email HTTP/1.0[0m" 500 -
2025-04-03 01:34:07,740 - INFO - 172.27.0.9 - - [03/Apr/2025 01:34:07] "[31m[1mPOST /bind-email HTTP/1.0[0m" 400 -
2025-04-03 01:34:09,424 - INFO - 172.27.0.9 - - [03/Apr/2025 01:34:09] "[31m[1mPOST /bind-email HTTP/1.0[0m" 400 -
2025-04-03 01:34:10,211 - INFO - 172.27.0.9 - - [03/Apr/2025 01:34:10] "[31m[1mPOST /bind-email HTTP/1.0[0m" 400 -
2025-04-03 01:34:20,434 - INFO - 172.27.0.9 - - [03/Apr/2025 01:34:20] "[31m[1mPOST /bind-email HTTP/1.0[0m" 400 -
2025-04-03 01:35:32,828 - INFO - 172.27.0.9 - - [03/Apr/2025 01:35:32] "[31m[1mPOST /bind-email HTTP/1.0[0m" 400 -
2025-04-03 01:45:16,598 - INFO - 172.27.0.9 - - [03/Apr/2025 01:45:16] "[31m[1mPOST /bind-email HTTP/1.0[0m" 400 -
2025-04-03 01:49:06,290 - INFO - 172.27.0.9 - - [03/Apr/2025 01:49:06] "[31m[1mPOST /bind-email HTTP/1.0[0m" 400 -
2025-04-03 01:49:10,947 - INFO - 172.27.0.9 - - [03/Apr/2025 01:49:10] "[31m[1mPOST /bind-email HTTP/1.0[0m" 400 -
2025-04-03 01:50:29,913 - INFO - 172.27.0.9 - - [03/Apr/2025 01:50:29] "[31m[1mPOST /bind-email HTTP/1.0[0m" 400 -
2025-04-03 01:53:54,335 - INFO - 172.27.0.9 - - [03/Apr/2025 01:53:54] "POST /bind-email HTTP/1.0" 200 -
2025-04-03 01:53:54,392 - INFO - 172.27.0.9 - - [03/Apr/2025 01:53:54] "GET /get_user_image HTTP/1.0" 200 -
2025-04-03 01:54:00,845 - INFO - 172.27.0.9 - - [03/Apr/2025 01:54:00] "[36mGET /get_user_image HTTP/1.0[0m" 304 -
2025-04-03 01:54:05,851 - INFO - 172.27.0.9 - - [03/Apr/2025 01:54:05] "[36mGET /get_user_image HTTP/1.0[0m" 304 -
2025-04-03 01:54:16,306 - INFO - 172.27.0.9 - - [03/Apr/2025 01:54:16] "POST /login HTTP/1.0" 200 -
2025-04-03 01:54:16,361 - INFO - 172.27.0.9 - - [03/Apr/2025 01:54:16] "GET /users HTTP/1.0" 200 -
2025-04-03 01:54:16,362 - INFO - 172.27.0.9 - - [03/Apr/2025 01:54:16] "GET /get_user_image HTTP/1.0" 200 -
2025-04-03 01:55:33,165 - INFO - 172.27.0.9 - - [03/Apr/2025 01:55:33] "POST /bind-email HTTP/1.0" 200 -
2025-04-03 01:55:33,200 - INFO - 172.27.0.9 - - [03/Apr/2025 01:55:33] "[36mGET /get_user_image HTTP/1.0[0m" 304 -
2025-04-03 01:55:45,752 - INFO - 172.27.0.9 - - [03/Apr/2025 01:55:45] "[36mGET /get_user_image HTTP/1.0[0m" 304 -
2025-04-03 01:55:58,233 - ERROR - Exception on /login [POST]
Traceback (most recent call last):
  File "/usr/local/lib/python3.9/site-packages/flask/app.py", line 2525, in wsgi_app
    response = self.full_dispatch_request()
  File "/usr/local/lib/python3.9/site-packages/flask/app.py", line 1822, in full_dispatch_request
    rv = self.handle_user_exception(e)
  File "/usr/local/lib/python3.9/site-packages/flask_cors/extension.py", line 176, in wrapped_function
    return cors_after_request(app.make_response(f(*args, **kwargs)))
  File "/usr/local/lib/python3.9/site-packages/flask/app.py", line 1820, in full_dispatch_request
    rv = self.dispatch_request()
  File "/usr/local/lib/python3.9/site-packages/flask/app.py", line 1796, in dispatch_request
    return self.ensure_sync(self.view_functions[rule.endpoint])(**view_args)
  File "/app/controllers/auth_controller.py", line 46, in login
    login_response = login_user(data)
  File "/app/services/user_service.py", line 35, in login_user
    if not user or not user.check_password(password):
  File "/app/models.py", line 39, in check_password
    return bcrypt.check_password_hash(self.password_hash, password)
  File "/usr/local/lib/python3.9/site-packages/flask_bcrypt.py", line 225, in check_password_hash
    return hmac.compare_digest(bcrypt.hashpw(password, pw_hash), pw_hash)
TypeError: argument 'salt': 'NoneType' object cannot be converted to 'PyBytes'
2025-04-03 01:55:58,240 - INFO - 172.27.0.9 - - [03/Apr/2025 01:55:58] "[35m[1mPOST /login HTTP/1.0[0m" 500 -
2025-04-03 01:56:04,076 - ERROR - Exception on /login [POST]
Traceback (most recent call last):
  File "/usr/local/lib/python3.9/site-packages/flask/app.py", line 2525, in wsgi_app
    response = self.full_dispatch_request()
  File "/usr/local/lib/python3.9/site-packages/flask/app.py", line 1822, in full_dispatch_request
    rv = self.handle_user_exception(e)
  File "/usr/local/lib/python3.9/site-packages/flask_cors/extension.py", line 176, in wrapped_function
    return cors_after_request(app.make_response(f(*args, **kwargs)))
  File "/usr/local/lib/python3.9/site-packages/flask/app.py", line 1820, in full_dispatch_request
    rv = self.dispatch_request()
  File "/usr/local/lib/python3.9/site-packages/flask/app.py", line 1796, in dispatch_request
    return self.ensure_sync(self.view_functions[rule.endpoint])(**view_args)
  File "/app/controllers/auth_controller.py", line 46, in login
    login_response = login_user(data)
  File "/app/services/user_service.py", line 35, in login_user
    if not user or not user.check_password(password):
  File "/app/models.py", line 39, in check_password
    return bcrypt.check_password_hash(self.password_hash, password)
  File "/usr/local/lib/python3.9/site-packages/flask_bcrypt.py", line 225, in check_password_hash
    return hmac.compare_digest(bcrypt.hashpw(password, pw_hash), pw_hash)
TypeError: argument 'salt': 'NoneType' object cannot be converted to 'PyBytes'
2025-04-03 01:56:04,084 - INFO - 172.27.0.9 - - [03/Apr/2025 01:56:04] "[35m[1mPOST /login HTTP/1.0[0m" 500 -
2025-04-03 01:56:07,624 - ERROR - Exception on /login [POST]
Traceback (most recent call last):
  File "/usr/local/lib/python3.9/site-packages/flask/app.py", line 2525, in wsgi_app
    response = self.full_dispatch_request()
  File "/usr/local/lib/python3.9/site-packages/flask/app.py", line 1822, in full_dispatch_request
    rv = self.handle_user_exception(e)
  File "/usr/local/lib/python3.9/site-packages/flask_cors/extension.py", line 176, in wrapped_function
    return cors_after_request(app.make_response(f(*args, **kwargs)))
  File "/usr/local/lib/python3.9/site-packages/flask/app.py", line 1820, in full_dispatch_request
    rv = self.dispatch_request()
  File "/usr/local/lib/python3.9/site-packages/flask/app.py", line 1796, in dispatch_request
    return self.ensure_sync(self.view_functions[rule.endpoint])(**view_args)
  File "/app/controllers/auth_controller.py", line 46, in login
    login_response = login_user(data)
  File "/app/services/user_service.py", line 35, in login_user
    if not user or not user.check_password(password):
  File "/app/models.py", line 39, in check_password
    return bcrypt.check_password_hash(self.password_hash, password)
  File "/usr/local/lib/python3.9/site-packages/flask_bcrypt.py", line 225, in check_password_hash
    return hmac.compare_digest(bcrypt.hashpw(password, pw_hash), pw_hash)
TypeError: argument 'salt': 'NoneType' object cannot be converted to 'PyBytes'
2025-04-03 01:56:07,626 - INFO - 172.27.0.9 - - [03/Apr/2025 01:56:07] "[35m[1mPOST /login HTTP/1.0[0m" 500 -
2025-04-03 01:56:31,998 - INFO - 172.27.0.9 - - [03/Apr/2025 01:56:31] "POST /bind-email HTTP/1.0" 200 -
2025-04-03 01:56:32,052 - INFO - 172.27.0.9 - - [03/Apr/2025 01:56:32] "[36mGET /get_user_image HTTP/1.0[0m" 304 -
2025-04-03 01:56:41,315 - INFO - 172.27.0.9 - - [03/Apr/2025 01:56:41] "POST /auth/google/callback HTTP/1.0" 200 -
2025-04-03 01:56:41,357 - INFO - 172.27.0.9 - - [03/Apr/2025 01:56:41] "GET /users HTTP/1.0" 200 -
2025-04-03 01:56:41,357 - INFO - 172.27.0.9 - - [03/Apr/2025 01:56:41] "GET /get_user_image HTTP/1.0" 200 -
2025-04-03 01:57:01,367 - INFO - 172.27.0.9 - - [03/Apr/2025 01:57:01] "POST /bind-email HTTP/1.0" 200 -
2025-04-03 01:57:01,414 - INFO - 172.27.0.9 - - [03/Apr/2025 01:57:01] "[36mGET /get_user_image HTTP/1.0[0m" 304 -
2025-04-03 01:57:07,435 - INFO - 172.27.0.9 - - [03/Apr/2025 01:57:07] "[36mGET /get_user_image HTTP/1.0[0m" 304 -
2025-04-03 07:08:06,764 - INFO - 172.27.0.9 - - [03/Apr/2025 07:08:06] "[33mGET /vendor/phpunit/phpunit/src/Util/PHP/eval-stdin.php HTTP/1.0[0m" 404 -
2025-04-03 07:09:59,113 - INFO - 172.27.0.9 - - [03/Apr/2025 07:09:59] "POST /bind-email HTTP/1.0" 200 -
2025-04-03 07:09:59,147 - INFO - 172.27.0.9 - - [03/Apr/2025 07:09:59] "[31m[1mGET /get_user_image HTTP/1.0[0m" 401 -
2025-04-03 07:10:32,846 - INFO - 172.27.0.9 - - [03/Apr/2025 07:10:32] "POST /bind-email HTTP/1.0" 200 -
2025-04-03 07:10:32,891 - INFO - 172.27.0.9 - - [03/Apr/2025 07:10:32] "[31m[1mGET /get_user_image HTTP/1.0[0m" 401 -
2025-04-03 07:10:47,701 - INFO - 172.27.0.9 - - [03/Apr/2025 07:10:47] "POST /login HTTP/1.0" 200 -
2025-04-03 07:10:47,737 - INFO - 172.27.0.9 - - [03/Apr/2025 07:10:47] "GET /get_user_image HTTP/1.0" 200 -
2025-04-03 07:10:51,696 - INFO - 172.27.0.9 - - [03/Apr/2025 07:10:51] "GET /users HTTP/1.0" 200 -
2025-04-03 07:13:35,952 - INFO - 172.27.0.9 - - [03/Apr/2025 07:13:35] "[36mGET /get_user_image HTTP/1.0[0m" 304 -
2025-04-03 07:13:35,960 - INFO - 172.27.0.9 - - [03/Apr/2025 07:13:35] "GET /users HTTP/1.0" 200 -
2025-04-03 07:13:52,743 - INFO - 172.27.0.9 - - [03/Apr/2025 07:13:52] "POST /bind-email HTTP/1.0" 200 -
2025-04-03 07:13:52,789 - INFO - 172.27.0.9 - - [03/Apr/2025 07:13:52] "[36mGET /get_user_image HTTP/1.0[0m" 304 -
2025-04-03 07:14:08,967 - INFO - 172.27.0.9 - - [03/Apr/2025 07:14:08] "GET /get_user_image HTTP/1.0" 200 -
2025-04-03 07:16:13,787 - INFO - 172.27.0.9 - - [03/Apr/2025 07:16:13] "POST /bind-email HTTP/1.0" 200 -
2025-04-03 07:21:15,003 - INFO - [31m[1mWARNING: This is a development server. Do not use it in a production deployment. Use a production WSGI server instead.[0m
 * Running on all addresses (0.0.0.0)
 * Running on http://127.0.0.1:5000
 * Running on http://172.27.0.7:5000
2025-04-03 07:21:15,004 - INFO - [33mPress CTRL+C to quit[0m
2025-04-03 07:21:15,021 - INFO - [31m[1mWARNING: This is a development server. Do not use it in a production deployment. Use a production WSGI server instead.[0m
 * Running on all addresses (0.0.0.0)
 * Running on http://127.0.0.1:5000
 * Running on http://172.27.0.8:5000
2025-04-03 07:21:15,022 - INFO - [33mPress CTRL+C to quit[0m
2025-04-03 07:21:34,481 - ERROR - Exception on /bind-email [POST]
Traceback (most recent call last):
  File "/usr/local/lib/python3.9/site-packages/flask/app.py", line 2525, in wsgi_app
    response = self.full_dispatch_request()
  File "/usr/local/lib/python3.9/site-packages/flask/app.py", line 1823, in full_dispatch_request
    return self.finalize_request(rv)
  File "/usr/local/lib/python3.9/site-packages/flask/app.py", line 1842, in finalize_request
    response = self.make_response(rv)
  File "/usr/local/lib/python3.9/site-packages/flask/app.py", line 2184, in make_response
    rv.status_code = status
  File "/usr/local/lib/python3.9/site-packages/werkzeug/sansio/response.py", line 182, in status_code
    self.status = code  # type: ignore
  File "/usr/local/lib/python3.9/site-packages/werkzeug/sansio/response.py", line 191, in status
    self._status, self._status_code = self._clean_status(value)
  File "/usr/local/lib/python3.9/site-packages/werkzeug/sansio/response.py", line 197, in _clean_status
    value = value.strip()
AttributeError: 'Response' object has no attribute 'strip'
2025-04-03 07:21:34,487 - INFO - 172.27.0.9 - - [03/Apr/2025 07:21:34] "[35m[1mPOST /bind-email HTTP/1.0[0m" 500 -
2025-04-03 07:21:53,247 - ERROR - Exception on /bind-email [POST]
Traceback (most recent call last):
  File "/usr/local/lib/python3.9/site-packages/flask/app.py", line 2525, in wsgi_app
    response = self.full_dispatch_request()
  File "/usr/local/lib/python3.9/site-packages/flask/app.py", line 1823, in full_dispatch_request
    return self.finalize_request(rv)
  File "/usr/local/lib/python3.9/site-packages/flask/app.py", line 1842, in finalize_request
    response = self.make_response(rv)
  File "/usr/local/lib/python3.9/site-packages/flask/app.py", line 2184, in make_response
    rv.status_code = status
  File "/usr/local/lib/python3.9/site-packages/werkzeug/sansio/response.py", line 182, in status_code
    self.status = code  # type: ignore
  File "/usr/local/lib/python3.9/site-packages/werkzeug/sansio/response.py", line 191, in status
    self._status, self._status_code = self._clean_status(value)
  File "/usr/local/lib/python3.9/site-packages/werkzeug/sansio/response.py", line 197, in _clean_status
    value = value.strip()
AttributeError: 'Response' object has no attribute 'strip'
2025-04-03 07:21:53,254 - INFO - 172.27.0.9 - - [03/Apr/2025 07:21:53] "[35m[1mPOST /bind-email HTTP/1.0[0m" 500 -
2025-04-03 07:24:04,811 - INFO - [31m[1mWARNING: This is a development server. Do not use it in a production deployment. Use a production WSGI server instead.[0m
 * Running on all addresses (0.0.0.0)
 * Running on http://127.0.0.1:5000
 * Running on http://172.27.0.8:5000
2025-04-03 07:24:04,812 - INFO - [33mPress CTRL+C to quit[0m
2025-04-03 07:24:04,812 - INFO - [31m[1mWARNING: This is a development server. Do not use it in a production deployment. Use a production WSGI server instead.[0m
 * Running on all addresses (0.0.0.0)
 * Running on http://127.0.0.1:5000
 * Running on http://172.27.0.7:5000
2025-04-03 07:24:04,813 - INFO - [33mPress CTRL+C to quit[0m
2025-04-03 07:24:25,473 - INFO - 172.27.0.9 - - [03/Apr/2025 07:24:25] "POST /bind-email HTTP/1.0" 200 -
2025-04-03 07:25:26,256 - INFO - 172.27.0.9 - - [03/Apr/2025 07:25:26] "[36mGET /get_user_image HTTP/1.0[0m" 304 -
2025-04-03 07:25:28,865 - INFO - 172.27.0.9 - - [03/Apr/2025 07:25:28] "GET /users HTTP/1.0" 200 -
2025-04-03 07:25:51,034 - INFO - 172.27.0.9 - - [03/Apr/2025 07:25:51] "GET /get_user_image HTTP/1.0" 200 -
2025-04-03 07:25:52,777 - INFO - 172.27.0.9 - - [03/Apr/2025 07:25:52] "GET /users HTTP/1.0" 200 -
2025-04-03 07:27:58,042 - INFO - [31m[1mWARNING: This is a development server. Do not use it in a production deployment. Use a production WSGI server instead.[0m
 * Running on all addresses (0.0.0.0)
 * Running on http://127.0.0.1:5000
 * Running on http://172.27.0.7:5000
2025-04-03 07:27:58,042 - INFO - [33mPress CTRL+C to quit[0m
2025-04-03 07:27:58,057 - INFO - [31m[1mWARNING: This is a development server. Do not use it in a production deployment. Use a production WSGI server instead.[0m
 * Running on all addresses (0.0.0.0)
 * Running on http://127.0.0.1:5000
 * Running on http://172.27.0.8:5000
2025-04-03 07:27:58,057 - INFO - [33mPress CTRL+C to quit[0m
2025-04-03 07:28:10,585 - INFO - 172.27.0.9 - - [03/Apr/2025 07:28:10] "[35m[1mPOST /bind-email HTTP/1.0[0m" 500 -
2025-04-03 07:29:52,961 - INFO - [31m[1mWARNING: This is a development server. Do not use it in a production deployment. Use a production WSGI server instead.[0m
 * Running on all addresses (0.0.0.0)
 * Running on http://127.0.0.1:5000
 * Running on http://172.27.0.7:5000
2025-04-03 07:29:52,962 - INFO - [33mPress CTRL+C to quit[0m
2025-04-03 07:29:53,010 - INFO - [31m[1mWARNING: This is a development server. Do not use it in a production deployment. Use a production WSGI server instead.[0m
 * Running on all addresses (0.0.0.0)
 * Running on http://127.0.0.1:5000
 * Running on http://172.27.0.8:5000
2025-04-03 07:29:53,010 - INFO - [33mPress CTRL+C to quit[0m
2025-04-03 07:40:06,686 - INFO - [31m[1mWARNING: This is a development server. Do not use it in a production deployment. Use a production WSGI server instead.[0m
 * Running on all addresses (0.0.0.0)
 * Running on http://127.0.0.1:5000
 * Running on http://172.27.0.7:5000
2025-04-03 07:40:06,686 - INFO - [33mPress CTRL+C to quit[0m
2025-04-03 07:40:06,702 - INFO - [31m[1mWARNING: This is a development server. Do not use it in a production deployment. Use a production WSGI server instead.[0m
 * Running on all addresses (0.0.0.0)
 * Running on http://127.0.0.1:5000
 * Running on http://172.27.0.8:5000
2025-04-03 07:40:06,702 - INFO - [33mPress CTRL+C to quit[0m
2025-04-03 07:40:26,913 - INFO - 172.27.0.9 - - [03/Apr/2025 07:40:26] "[35m[1mPOST /bind-email HTTP/1.0[0m" 500 -
2025-04-03 07:42:11,440 - INFO - [31m[1mWARNING: This is a development server. Do not use it in a production deployment. Use a production WSGI server instead.[0m
 * Running on all addresses (0.0.0.0)
 * Running on http://127.0.0.1:5000
 * Running on http://172.27.0.8:5000
2025-04-03 07:42:11,441 - INFO - [33mPress CTRL+C to quit[0m
2025-04-03 07:42:11,463 - INFO - [31m[1mWARNING: This is a development server. Do not use it in a production deployment. Use a production WSGI server instead.[0m
 * Running on all addresses (0.0.0.0)
 * Running on http://127.0.0.1:5000
 * Running on http://172.27.0.7:5000
2025-04-03 07:42:11,463 - INFO - [33mPress CTRL+C to quit[0m
2025-04-03 07:42:15,976 - INFO - 172.27.0.9 - - [03/Apr/2025 07:42:15] "[35m[1mPOST /bind-email HTTP/1.0[0m" 500 -
2025-04-03 07:44:05,873 - INFO - [31m[1mWARNING: This is a development server. Do not use it in a production deployment. Use a production WSGI server instead.[0m
 * Running on all addresses (0.0.0.0)
 * Running on http://127.0.0.1:5000
 * Running on http://172.27.0.8:5000
2025-04-03 07:44:05,874 - INFO - [33mPress CTRL+C to quit[0m
2025-04-03 07:44:06,036 - INFO - [31m[1mWARNING: This is a development server. Do not use it in a production deployment. Use a production WSGI server instead.[0m
 * Running on all addresses (0.0.0.0)
 * Running on http://127.0.0.1:5000
 * Running on http://172.27.0.7:5000
2025-04-03 07:44:06,037 - INFO - [33mPress CTRL+C to quit[0m
2025-04-03 07:44:19,255 - ERROR - ç™¼ç”ŸéŒ¯èª¤: local variable 'response' referenced before assignment
Traceback (most recent call last):
  File "/app/services/webhook_service.py", line 107, in bind_email_service
    response.set_cookie("user_id", str(user.id), httponly=True, secure=True, samesite="Strict")
UnboundLocalError: local variable 'response' referenced before assignment
2025-04-03 07:44:19,258 - INFO - 172.27.0.9 - - [03/Apr/2025 07:44:19] "[35m[1mPOST /bind-email HTTP/1.0[0m" 500 -
2025-04-03 07:45:02,213 - INFO - [31m[1mWARNING: This is a development server. Do not use it in a production deployment. Use a production WSGI server instead.[0m
 * Running on all addresses (0.0.0.0)
 * Running on http://127.0.0.1:5000
 * Running on http://172.27.0.7:5000
2025-04-03 07:45:02,214 - INFO - [33mPress CTRL+C to quit[0m
2025-04-03 07:45:02,296 - INFO - [31m[1mWARNING: This is a development server. Do not use it in a production deployment. Use a production WSGI server instead.[0m
 * Running on all addresses (0.0.0.0)
 * Running on http://127.0.0.1:5000
 * Running on http://172.27.0.8:5000
2025-04-03 07:45:02,296 - INFO - [33mPress CTRL+C to quit[0m
2025-04-03 07:45:13,224 - INFO - 172.27.0.9 - - [03/Apr/2025 07:45:13] "POST /bind-email HTTP/1.0" 200 -
2025-04-03 07:45:19,306 - INFO - 172.27.0.9 - - [03/Apr/2025 07:45:19] "GET /get_user_image HTTP/1.0" 200 -
2025-04-03 07:45:22,176 - INFO - 172.27.0.9 - - [03/Apr/2025 07:45:22] "GET /users HTTP/1.0" 200 -
2025-04-03 07:46:16,796 - INFO - 172.27.0.9 - - [03/Apr/2025 07:46:16] "POST /auth/google/callback HTTP/1.0" 200 -
2025-04-03 07:46:16,884 - INFO - 172.27.0.9 - - [03/Apr/2025 07:46:16] "GET /get_user_image HTTP/1.0" 200 -
2025-04-03 07:46:18,564 - INFO - 172.27.0.9 - - [03/Apr/2025 07:46:18] "GET /users HTTP/1.0" 200 -
2025-04-03 07:48:09,201 - INFO - [31m[1mWARNING: This is a development server. Do not use it in a production deployment. Use a production WSGI server instead.[0m
 * Running on all addresses (0.0.0.0)
 * Running on http://127.0.0.1:5000
 * Running on http://172.27.0.8:5000
2025-04-03 07:48:09,201 - INFO - [33mPress CTRL+C to quit[0m
2025-04-03 07:48:09,241 - INFO - [31m[1mWARNING: This is a development server. Do not use it in a production deployment. Use a production WSGI server instead.[0m
 * Running on all addresses (0.0.0.0)
 * Running on http://127.0.0.1:5000
 * Running on http://172.27.0.7:5000
2025-04-03 07:48:09,242 - INFO - [33mPress CTRL+C to quit[0m
2025-04-03 07:48:51,517 - INFO - 172.27.0.9 - - [03/Apr/2025 07:48:51] "POST /bind-email HTTP/1.0" 200 -
2025-04-03 07:48:51,573 - INFO - 172.27.0.9 - - [03/Apr/2025 07:48:51] "GET /users HTTP/1.0" 200 -
2025-04-03 07:48:51,603 - INFO - 172.27.0.9 - - [03/Apr/2025 07:48:51] "[36mGET /get_user_image HTTP/1.0[0m" 304 -
2025-04-03 07:50:23,971 - INFO - [31m[1mWARNING: This is a development server. Do not use it in a production deployment. Use a production WSGI server instead.[0m
 * Running on all addresses (0.0.0.0)
 * Running on http://127.0.0.1:5000
 * Running on http://172.27.0.7:5000
2025-04-03 07:50:23,972 - INFO - [33mPress CTRL+C to quit[0m
2025-04-03 07:50:23,999 - INFO - [31m[1mWARNING: This is a development server. Do not use it in a production deployment. Use a production WSGI server instead.[0m
 * Running on all addresses (0.0.0.0)
 * Running on http://127.0.0.1:5000
 * Running on http://172.27.0.8:5000
2025-04-03 07:50:23,999 - INFO - [33mPress CTRL+C to quit[0m
2025-04-03 07:51:07,165 - INFO - 172.27.0.9 - - [03/Apr/2025 07:51:07] "POST /bind-email HTTP/1.0" 200 -
2025-04-03 07:51:07,219 - INFO - 172.27.0.9 - - [03/Apr/2025 07:51:07] "GET /users HTTP/1.0" 200 -
2025-04-03 07:51:07,258 - INFO - 172.27.0.9 - - [03/Apr/2025 07:51:07] "[36mGET /get_user_image HTTP/1.0[0m" 304 -
2025-04-03 07:51:52,871 - INFO - 172.27.0.9 - - [03/Apr/2025 07:51:52] "POST /bind-email HTTP/1.0" 200 -
2025-04-03 07:52:03,785 - INFO - 172.27.0.9 - - [03/Apr/2025 07:52:03] "POST /bind-email HTTP/1.0" 200 -
2025-04-03 07:52:28,126 - INFO - 172.27.0.9 - - [03/Apr/2025 07:52:28] "[36mGET /get_user_image HTTP/1.0[0m" 304 -
2025-04-03 07:52:29,073 - INFO - 172.27.0.9 - - [03/Apr/2025 07:52:29] "GET /users HTTP/1.0" 200 -
2025-04-03 07:52:57,662 - ERROR - Exception on /login [POST]
Traceback (most recent call last):
  File "/usr/local/lib/python3.9/site-packages/flask/app.py", line 2525, in wsgi_app
    response = self.full_dispatch_request()
  File "/usr/local/lib/python3.9/site-packages/flask/app.py", line 1822, in full_dispatch_request
    rv = self.handle_user_exception(e)
  File "/usr/local/lib/python3.9/site-packages/flask_cors/extension.py", line 176, in wrapped_function
    return cors_after_request(app.make_response(f(*args, **kwargs)))
  File "/usr/local/lib/python3.9/site-packages/flask/app.py", line 1820, in full_dispatch_request
    rv = self.dispatch_request()
  File "/usr/local/lib/python3.9/site-packages/flask/app.py", line 1796, in dispatch_request
    return self.ensure_sync(self.view_functions[rule.endpoint])(**view_args)
  File "/app/controllers/auth_controller.py", line 46, in login
    login_response = login_user(data)
  File "/app/services/user_service.py", line 35, in login_user
    if not user or not user.check_password(password):
  File "/app/models.py", line 39, in check_password
    return bcrypt.check_password_hash(self.password_hash, password)
  File "/usr/local/lib/python3.9/site-packages/flask_bcrypt.py", line 225, in check_password_hash
    return hmac.compare_digest(bcrypt.hashpw(password, pw_hash), pw_hash)
TypeError: argument 'salt': 'NoneType' object cannot be converted to 'PyBytes'
2025-04-03 07:52:57,670 - INFO - 172.27.0.9 - - [03/Apr/2025 07:52:57] "[35m[1mPOST /login HTTP/1.0[0m" 500 -
2025-04-03 07:53:18,298 - ERROR - ç™¼ç”ŸéŒ¯èª¤: argument 'salt': 'NoneType' object cannot be converted to 'PyBytes'
Traceback (most recent call last):
  File "/app/services/webhook_service.py", line 80, in bind_email_service
    if password and not user.check_password(password):
  File "/app/models.py", line 39, in check_password
    return bcrypt.check_password_hash(self.password_hash, password)
  File "/usr/local/lib/python3.9/site-packages/flask_bcrypt.py", line 225, in check_password_hash
    return hmac.compare_digest(bcrypt.hashpw(password, pw_hash), pw_hash)
TypeError: argument 'salt': 'NoneType' object cannot be converted to 'PyBytes'
2025-04-03 07:53:18,303 - INFO - 172.27.0.9 - - [03/Apr/2025 07:53:18] "[35m[1mPOST /bind-email HTTP/1.0[0m" 500 -
2025-04-03 07:55:21,745 - ERROR - ç™¼ç”ŸéŒ¯èª¤: argument 'salt': 'NoneType' object cannot be converted to 'PyBytes'
Traceback (most recent call last):
  File "/app/services/webhook_service.py", line 80, in bind_email_service
    if password and not user.check_password(password):
  File "/app/models.py", line 39, in check_password
    return bcrypt.check_password_hash(self.password_hash, password)
  File "/usr/local/lib/python3.9/site-packages/flask_bcrypt.py", line 225, in check_password_hash
    return hmac.compare_digest(bcrypt.hashpw(password, pw_hash), pw_hash)
TypeError: argument 'salt': 'NoneType' object cannot be converted to 'PyBytes'
2025-04-03 07:55:21,747 - INFO - 172.27.0.9 - - [03/Apr/2025 07:55:21] "[35m[1mPOST /bind-email HTTP/1.0[0m" 500 -
2025-04-03 07:55:34,913 - ERROR - ç™¼ç”ŸéŒ¯èª¤: argument 'salt': 'NoneType' object cannot be converted to 'PyBytes'
Traceback (most recent call last):
  File "/app/services/webhook_service.py", line 80, in bind_email_service
    if password and not user.check_password(password):
  File "/app/models.py", line 39, in check_password
    return bcrypt.check_password_hash(self.password_hash, password)
  File "/usr/local/lib/python3.9/site-packages/flask_bcrypt.py", line 225, in check_password_hash
    return hmac.compare_digest(bcrypt.hashpw(password, pw_hash), pw_hash)
TypeError: argument 'salt': 'NoneType' object cannot be converted to 'PyBytes'
2025-04-03 07:55:34,915 - INFO - 172.27.0.9 - - [03/Apr/2025 07:55:34] "[35m[1mPOST /bind-email HTTP/1.0[0m" 500 -
2025-04-03 07:59:53,192 - INFO - 172.27.0.9 - - [03/Apr/2025 07:59:53] "POST /auth/google/callback HTTP/1.0" 200 -
2025-04-03 07:59:53,227 - INFO - 172.27.0.9 - - [03/Apr/2025 07:59:53] "GET /get_user_image HTTP/1.0" 200 -
2025-04-03 07:59:53,238 - INFO - 172.27.0.9 - - [03/Apr/2025 07:59:53] "GET /users HTTP/1.0" 200 -
2025-04-03 08:00:40,403 - ERROR - ç™¼ç”ŸéŒ¯èª¤: argument 'salt': 'NoneType' object cannot be converted to 'PyBytes'
Traceback (most recent call last):
  File "/app/services/webhook_service.py", line 80, in bind_email_service
    if password and not user.check_password(password):
  File "/app/models.py", line 39, in check_password
    return bcrypt.check_password_hash(self.password_hash, password)
  File "/usr/local/lib/python3.9/site-packages/flask_bcrypt.py", line 225, in check_password_hash
    return hmac.compare_digest(bcrypt.hashpw(password, pw_hash), pw_hash)
TypeError: argument 'salt': 'NoneType' object cannot be converted to 'PyBytes'
2025-04-03 08:00:40,405 - INFO - 172.27.0.9 - - [03/Apr/2025 08:00:40] "[35m[1mPOST /bind-email HTTP/1.0[0m" 500 -
2025-04-03 08:00:42,089 - ERROR - ç™¼ç”ŸéŒ¯èª¤: argument 'salt': 'NoneType' object cannot be converted to 'PyBytes'
Traceback (most recent call last):
  File "/app/services/webhook_service.py", line 80, in bind_email_service
    if password and not user.check_password(password):
  File "/app/models.py", line 39, in check_password
    return bcrypt.check_password_hash(self.password_hash, password)
  File "/usr/local/lib/python3.9/site-packages/flask_bcrypt.py", line 225, in check_password_hash
    return hmac.compare_digest(bcrypt.hashpw(password, pw_hash), pw_hash)
TypeError: argument 'salt': 'NoneType' object cannot be converted to 'PyBytes'
2025-04-03 08:00:42,092 - INFO - 172.27.0.9 - - [03/Apr/2025 08:00:42] "[35m[1mPOST /bind-email HTTP/1.0[0m" 500 -
2025-04-03 08:03:42,193 - INFO - [31m[1mWARNING: This is a development server. Do not use it in a production deployment. Use a production WSGI server instead.[0m
 * Running on all addresses (0.0.0.0)
 * Running on http://127.0.0.1:5000
 * Running on http://172.27.0.7:5000
2025-04-03 08:03:42,194 - INFO - [33mPress CTRL+C to quit[0m
2025-04-03 08:03:42,208 - INFO - [31m[1mWARNING: This is a development server. Do not use it in a production deployment. Use a production WSGI server instead.[0m
 * Running on all addresses (0.0.0.0)
 * Running on http://127.0.0.1:5000
 * Running on http://172.27.0.8:5000
2025-04-03 08:03:42,208 - INFO - [33mPress CTRL+C to quit[0m
2025-04-03 08:03:42,928 - INFO - 172.27.0.9 - - [03/Apr/2025 08:03:42] "[36mGET /get_user_image HTTP/1.0[0m" 304 -
2025-04-03 08:03:44,484 - INFO - 172.27.0.9 - - [03/Apr/2025 08:03:44] "GET /users HTTP/1.0" 200 -
2025-04-03 08:03:56,043 - INFO - 172.27.0.9 - - [03/Apr/2025 08:03:56] "POST /login HTTP/1.0" 200 -
2025-04-03 08:03:56,117 - INFO - 172.27.0.9 - - [03/Apr/2025 08:03:56] "GET /get_user_image HTTP/1.0" 200 -
2025-04-03 08:04:01,908 - INFO - 172.27.0.9 - - [03/Apr/2025 08:04:01] "GET /users HTTP/1.0" 200 -
2025-04-03 08:04:20,251 - ERROR - ç™¼ç”ŸéŒ¯èª¤: (psycopg2.errors.UniqueViolation) duplicate key value violates unique constraint "unique_line_id"
DETAIL:  Key (line_id)=(U627d1e440f23a15363f9720fc7c79b3e                                                                                       ) already exists.

[SQL: INSERT INTO line_binding_user (line_id, created_at, user_id) VALUES (%(line_id)s, %(created_at)s, %(user_id)s)]
[parameters: {'line_id': 'U627d1e440f23a15363f9720fc7c79b3e', 'created_at': datetime.datetime(2025, 4, 3, 8, 4, 20, 248789), 'user_id': 1}]
(Background on this error at: https://sqlalche.me/e/20/gkpj)
Traceback (most recent call last):
  File "/usr/local/lib/python3.9/site-packages/sqlalchemy/engine/base.py", line 1964, in _exec_single_context
    self.dialect.do_execute(
  File "/usr/local/lib/python3.9/site-packages/sqlalchemy/engine/default.py", line 945, in do_execute
    cursor.execute(statement, parameters)
psycopg2.errors.UniqueViolation: duplicate key value violates unique constraint "unique_line_id"
DETAIL:  Key (line_id)=(U627d1e440f23a15363f9720fc7c79b3e                                                                                       ) already exists.


The above exception was the direct cause of the following exception:

Traceback (most recent call last):
  File "/app/services/webhook_service.py", line 90, in bind_email_service
    db.session.commit()
  File "/usr/local/lib/python3.9/site-packages/sqlalchemy/orm/scoping.py", line 599, in commit
    return self._proxied.commit()
  File "/usr/local/lib/python3.9/site-packages/sqlalchemy/orm/session.py", line 2032, in commit
    trans.commit(_to_root=True)
  File "<string>", line 2, in commit
  File "/usr/local/lib/python3.9/site-packages/sqlalchemy/orm/state_changes.py", line 139, in _go
    ret_value = fn(self, *arg, **kw)
  File "/usr/local/lib/python3.9/site-packages/sqlalchemy/orm/session.py", line 1313, in commit
    self._prepare_impl()
  File "<string>", line 2, in _prepare_impl
  File "/usr/local/lib/python3.9/site-packages/sqlalchemy/orm/state_changes.py", line 139, in _go
    ret_value = fn(self, *arg, **kw)
  File "/usr/local/lib/python3.9/site-packages/sqlalchemy/orm/session.py", line 1288, in _prepare_impl
    self.session.flush()
  File "/usr/local/lib/python3.9/site-packages/sqlalchemy/orm/session.py", line 4353, in flush
    self._flush(objects)
  File "/usr/local/lib/python3.9/site-packages/sqlalchemy/orm/session.py", line 4489, in _flush
    transaction.rollback(_capture_exception=True)
  File "/usr/local/lib/python3.9/site-packages/sqlalchemy/util/langhelpers.py", line 146, in __exit__
    raise exc_value.with_traceback(exc_tb)
  File "/usr/local/lib/python3.9/site-packages/sqlalchemy/orm/session.py", line 4449, in _flush
    flush_context.execute()
  File "/usr/local/lib/python3.9/site-packages/sqlalchemy/orm/unitofwork.py", line 466, in execute
    rec.execute(self)
  File "/usr/local/lib/python3.9/site-packages/sqlalchemy/orm/unitofwork.py", line 642, in execute
    util.preloaded.orm_persistence.save_obj(
  File "/usr/local/lib/python3.9/site-packages/sqlalchemy/orm/persistence.py", line 93, in save_obj
    _emit_insert_statements(
  File "/usr/local/lib/python3.9/site-packages/sqlalchemy/orm/persistence.py", line 1048, in _emit_insert_statements
    result = connection.execute(
  File "/usr/local/lib/python3.9/site-packages/sqlalchemy/engine/base.py", line 1416, in execute
    return meth(
  File "/usr/local/lib/python3.9/site-packages/sqlalchemy/sql/elements.py", line 523, in _execute_on_connection
    return connection._execute_clauseelement(
  File "/usr/local/lib/python3.9/site-packages/sqlalchemy/engine/base.py", line 1638, in _execute_clauseelement
    ret = self._execute_context(
  File "/usr/local/lib/python3.9/site-packages/sqlalchemy/engine/base.py", line 1843, in _execute_context
    return self._exec_single_context(
  File "/usr/local/lib/python3.9/site-packages/sqlalchemy/engine/base.py", line 1983, in _exec_single_context
    self._handle_dbapi_exception(
  File "/usr/local/lib/python3.9/site-packages/sqlalchemy/engine/base.py", line 2352, in _handle_dbapi_exception
    raise sqlalchemy_exception.with_traceback(exc_info[2]) from e
  File "/usr/local/lib/python3.9/site-packages/sqlalchemy/engine/base.py", line 1964, in _exec_single_context
    self.dialect.do_execute(
  File "/usr/local/lib/python3.9/site-packages/sqlalchemy/engine/default.py", line 945, in do_execute
    cursor.execute(statement, parameters)
sqlalchemy.exc.IntegrityError: (psycopg2.errors.UniqueViolation) duplicate key value violates unique constraint "unique_line_id"
DETAIL:  Key (line_id)=(U627d1e440f23a15363f9720fc7c79b3e                                                                                       ) already exists.

[SQL: INSERT INTO line_binding_user (line_id, created_at, user_id) VALUES (%(line_id)s, %(created_at)s, %(user_id)s)]
[parameters: {'line_id': 'U627d1e440f23a15363f9720fc7c79b3e', 'created_at': datetime.datetime(2025, 4, 3, 8, 4, 20, 248789), 'user_id': 1}]
(Background on this error at: https://sqlalche.me/e/20/gkpj)
2025-04-03 08:04:20,268 - INFO - 172.27.0.9 - - [03/Apr/2025 08:04:20] "[35m[1mPOST /bind-email HTTP/1.0[0m" 500 -
2025-04-03 08:04:38,266 - ERROR - ç™¼ç”ŸéŒ¯èª¤: argument 'salt': 'NoneType' object cannot be converted to 'PyBytes'
Traceback (most recent call last):
  File "/app/services/webhook_service.py", line 80, in bind_email_service
    if not user.check_password(password):
  File "/app/models.py", line 39, in check_password
    return bcrypt.check_password_hash(self.password_hash, password)
  File "/usr/local/lib/python3.9/site-packages/flask_bcrypt.py", line 225, in check_password_hash
    return hmac.compare_digest(bcrypt.hashpw(password, pw_hash), pw_hash)
TypeError: argument 'salt': 'NoneType' object cannot be converted to 'PyBytes'
2025-04-03 08:04:38,269 - INFO - 172.27.0.9 - - [03/Apr/2025 08:04:38] "[35m[1mPOST /bind-email HTTP/1.0[0m" 500 -
2025-04-03 08:04:39,975 - ERROR - ç™¼ç”ŸéŒ¯èª¤: argument 'salt': 'NoneType' object cannot be converted to 'PyBytes'
Traceback (most recent call last):
  File "/app/services/webhook_service.py", line 80, in bind_email_service
    if not user.check_password(password):
  File "/app/models.py", line 39, in check_password
    return bcrypt.check_password_hash(self.password_hash, password)
  File "/usr/local/lib/python3.9/site-packages/flask_bcrypt.py", line 225, in check_password_hash
    return hmac.compare_digest(bcrypt.hashpw(password, pw_hash), pw_hash)
TypeError: argument 'salt': 'NoneType' object cannot be converted to 'PyBytes'
2025-04-03 08:04:39,978 - INFO - 172.27.0.9 - - [03/Apr/2025 08:04:39] "[35m[1mPOST /bind-email HTTP/1.0[0m" 500 -
2025-04-03 08:04:40,614 - ERROR - ç™¼ç”ŸéŒ¯èª¤: argument 'salt': 'NoneType' object cannot be converted to 'PyBytes'
Traceback (most recent call last):
  File "/app/services/webhook_service.py", line 80, in bind_email_service
    if not user.check_password(password):
  File "/app/models.py", line 39, in check_password
    return bcrypt.check_password_hash(self.password_hash, password)
  File "/usr/local/lib/python3.9/site-packages/flask_bcrypt.py", line 225, in check_password_hash
    return hmac.compare_digest(bcrypt.hashpw(password, pw_hash), pw_hash)
TypeError: argument 'salt': 'NoneType' object cannot be converted to 'PyBytes'
2025-04-03 08:04:40,616 - INFO - 172.27.0.9 - - [03/Apr/2025 08:04:40] "[35m[1mPOST /bind-email HTTP/1.0[0m" 500 -
2025-04-03 08:04:40,899 - ERROR - ç™¼ç”ŸéŒ¯èª¤: argument 'salt': 'NoneType' object cannot be converted to 'PyBytes'
Traceback (most recent call last):
  File "/app/services/webhook_service.py", line 80, in bind_email_service
    if not user.check_password(password):
  File "/app/models.py", line 39, in check_password
    return bcrypt.check_password_hash(self.password_hash, password)
  File "/usr/local/lib/python3.9/site-packages/flask_bcrypt.py", line 225, in check_password_hash
    return hmac.compare_digest(bcrypt.hashpw(password, pw_hash), pw_hash)
TypeError: argument 'salt': 'NoneType' object cannot be converted to 'PyBytes'
2025-04-03 08:04:40,901 - INFO - 172.27.0.9 - - [03/Apr/2025 08:04:40] "[35m[1mPOST /bind-email HTTP/1.0[0m" 500 -
2025-04-03 08:04:54,259 - ERROR - Exception on /login [POST]
Traceback (most recent call last):
  File "/usr/local/lib/python3.9/site-packages/flask/app.py", line 2525, in wsgi_app
    response = self.full_dispatch_request()
  File "/usr/local/lib/python3.9/site-packages/flask/app.py", line 1822, in full_dispatch_request
    rv = self.handle_user_exception(e)
  File "/usr/local/lib/python3.9/site-packages/flask_cors/extension.py", line 176, in wrapped_function
    return cors_after_request(app.make_response(f(*args, **kwargs)))
  File "/usr/local/lib/python3.9/site-packages/flask/app.py", line 1820, in full_dispatch_request
    rv = self.dispatch_request()
  File "/usr/local/lib/python3.9/site-packages/flask/app.py", line 1796, in dispatch_request
    return self.ensure_sync(self.view_functions[rule.endpoint])(**view_args)
  File "/app/controllers/auth_controller.py", line 46, in login
    login_response = login_user(data)
  File "/app/services/user_service.py", line 35, in login_user
    if not user or not user.check_password(password):
  File "/app/models.py", line 39, in check_password
    return bcrypt.check_password_hash(self.password_hash, password)
  File "/usr/local/lib/python3.9/site-packages/flask_bcrypt.py", line 225, in check_password_hash
    return hmac.compare_digest(bcrypt.hashpw(password, pw_hash), pw_hash)
TypeError: argument 'salt': 'NoneType' object cannot be converted to 'PyBytes'
2025-04-03 08:04:54,263 - INFO - 172.27.0.9 - - [03/Apr/2025 08:04:54] "[35m[1mPOST /login HTTP/1.0[0m" 500 -
2025-04-03 08:04:55,771 - ERROR - Exception on /login [POST]
Traceback (most recent call last):
  File "/usr/local/lib/python3.9/site-packages/flask/app.py", line 2525, in wsgi_app
    response = self.full_dispatch_request()
  File "/usr/local/lib/python3.9/site-packages/flask/app.py", line 1822, in full_dispatch_request
    rv = self.handle_user_exception(e)
  File "/usr/local/lib/python3.9/site-packages/flask_cors/extension.py", line 176, in wrapped_function
    return cors_after_request(app.make_response(f(*args, **kwargs)))
  File "/usr/local/lib/python3.9/site-packages/flask/app.py", line 1820, in full_dispatch_request
    rv = self.dispatch_request()
  File "/usr/local/lib/python3.9/site-packages/flask/app.py", line 1796, in dispatch_request
    return self.ensure_sync(self.view_functions[rule.endpoint])(**view_args)
  File "/app/controllers/auth_controller.py", line 46, in login
    login_response = login_user(data)
  File "/app/services/user_service.py", line 35, in login_user
    if not user or not user.check_password(password):
  File "/app/models.py", line 39, in check_password
    return bcrypt.check_password_hash(self.password_hash, password)
  File "/usr/local/lib/python3.9/site-packages/flask_bcrypt.py", line 225, in check_password_hash
    return hmac.compare_digest(bcrypt.hashpw(password, pw_hash), pw_hash)
TypeError: argument 'salt': 'NoneType' object cannot be converted to 'PyBytes'
2025-04-03 08:04:55,776 - INFO - 172.27.0.9 - - [03/Apr/2025 08:04:55] "[35m[1mPOST /login HTTP/1.0[0m" 500 -
2025-04-03 08:07:29,112 - INFO - 172.27.0.9 - - [03/Apr/2025 08:07:29] "POST /login HTTP/1.0" 200 -
2025-04-03 08:07:29,144 - INFO - 172.27.0.9 - - [03/Apr/2025 08:07:29] "GET /users HTTP/1.0" 200 -
2025-04-03 08:07:29,146 - INFO - 172.27.0.9 - - [03/Apr/2025 08:07:29] "GET /get_user_image HTTP/1.0" 200 -
2025-04-03 10:17:10,460 - INFO - [31m[1mWARNING: This is a development server. Do not use it in a production deployment. Use a production WSGI server instead.[0m
 * Running on all addresses (0.0.0.0)
 * Running on http://127.0.0.1:5000
 * Running on http://172.28.0.7:5000
2025-04-03 10:17:10,461 - INFO - [33mPress CTRL+C to quit[0m
2025-04-03 10:17:10,490 - INFO - [31m[1mWARNING: This is a development server. Do not use it in a production deployment. Use a production WSGI server instead.[0m
 * Running on all addresses (0.0.0.0)
 * Running on http://127.0.0.1:5000
 * Running on http://172.28.0.8:5000
2025-04-03 10:17:10,491 - INFO - [33mPress CTRL+C to quit[0m
2025-04-03 10:17:21,920 - ERROR - Exception on /login [POST]
Traceback (most recent call last):
  File "/usr/local/lib/python3.9/site-packages/sqlalchemy/orm/mapper.py", line 2522, in get_property
    return self._props[key]
KeyError: 'email_verification'

The above exception was the direct cause of the following exception:

Traceback (most recent call last):
  File "/usr/local/lib/python3.9/site-packages/flask/app.py", line 2525, in wsgi_app
    response = self.full_dispatch_request()
  File "/usr/local/lib/python3.9/site-packages/flask/app.py", line 1822, in full_dispatch_request
    rv = self.handle_user_exception(e)
  File "/usr/local/lib/python3.9/site-packages/flask/app.py", line 1820, in full_dispatch_request
    rv = self.dispatch_request()
  File "/usr/local/lib/python3.9/site-packages/flask/app.py", line 1796, in dispatch_request
    return self.ensure_sync(self.view_functions[rule.endpoint])(**view_args)
  File "/app/controllers/auth_controller.py", line 46, in login
    login_response = login_user(data)
  File "/app/services/user_service.py", line 34, in login_user
    user = User.query.filter_by(username=username).first()
  File "/usr/local/lib/python3.9/site-packages/flask_sqlalchemy/model.py", line 30, in __get__
    return cls.query_class(
  File "/usr/local/lib/python3.9/site-packages/sqlalchemy/orm/query.py", line 276, in __init__
    self._set_entities(entities)
  File "/usr/local/lib/python3.9/site-packages/sqlalchemy/orm/query.py", line 288, in _set_entities
    self._raw_columns = [
  File "/usr/local/lib/python3.9/site-packages/sqlalchemy/orm/query.py", line 289, in <listcomp>
    coercions.expect(
  File "/usr/local/lib/python3.9/site-packages/sqlalchemy/sql/coercions.py", line 388, in expect
    insp._post_inspect
  File "/usr/local/lib/python3.9/site-packages/sqlalchemy/util/langhelpers.py", line 1257, in __get__
    obj.__dict__[self.__name__] = result = self.fget(obj)
  File "/usr/local/lib/python3.9/site-packages/sqlalchemy/orm/mapper.py", line 2724, in _post_inspect
    self._check_configure()
  File "/usr/local/lib/python3.9/site-packages/sqlalchemy/orm/mapper.py", line 2401, in _check_configure
    _configure_registries({self.registry}, cascade=True)
  File "/usr/local/lib/python3.9/site-packages/sqlalchemy/orm/mapper.py", line 4214, in _configure_registries
    _do_configure_registries(registries, cascade)
  File "/usr/local/lib/python3.9/site-packages/sqlalchemy/orm/mapper.py", line 4255, in _do_configure_registries
    mapper._post_configure_properties()
  File "/usr/local/lib/python3.9/site-packages/sqlalchemy/orm/mapper.py", line 2418, in _post_configure_properties
    prop.init()
  File "/usr/local/lib/python3.9/site-packages/sqlalchemy/orm/interfaces.py", line 589, in init
    self.do_init()
  File "/usr/local/lib/python3.9/site-packages/sqlalchemy/orm/relationships.py", line 1661, in do_init
    self._generate_backref()
  File "/usr/local/lib/python3.9/site-packages/sqlalchemy/orm/relationships.py", line 2147, in _generate_backref
    self._add_reverse_property(self.back_populates)
  File "/usr/local/lib/python3.9/site-packages/sqlalchemy/orm/relationships.py", line 1592, in _add_reverse_property
    other = self.mapper.get_property(key, _configure_mappers=False)
  File "/usr/local/lib/python3.9/site-packages/sqlalchemy/orm/mapper.py", line 2524, in get_property
    raise sa_exc.InvalidRequestError(
sqlalchemy.exc.InvalidRequestError: Mapper 'Mapper[User(users)]' has no property 'email_verification'.  If this property was indicated from other mappers or configure events, ensure registry.configure() has been called.
2025-04-03 10:17:21,936 - INFO - 172.28.0.9 - - [03/Apr/2025 10:17:21] "[35m[1mPOST /login HTTP/1.0[0m" 500 -
2025-04-03 10:17:23,214 - ERROR - Exception on /login [POST]
Traceback (most recent call last):
  File "/usr/local/lib/python3.9/site-packages/sqlalchemy/orm/mapper.py", line 2522, in get_property
    return self._props[key]
KeyError: 'email_verification'

The above exception was the direct cause of the following exception:

Traceback (most recent call last):
  File "/usr/local/lib/python3.9/site-packages/flask/app.py", line 2525, in wsgi_app
    response = self.full_dispatch_request()
  File "/usr/local/lib/python3.9/site-packages/flask/app.py", line 1822, in full_dispatch_request
    rv = self.handle_user_exception(e)
  File "/usr/local/lib/python3.9/site-packages/flask/app.py", line 1820, in full_dispatch_request
    rv = self.dispatch_request()
  File "/usr/local/lib/python3.9/site-packages/flask/app.py", line 1796, in dispatch_request
    return self.ensure_sync(self.view_functions[rule.endpoint])(**view_args)
  File "/app/controllers/auth_controller.py", line 46, in login
    login_response = login_user(data)
  File "/app/services/user_service.py", line 34, in login_user
    user = User.query.filter_by(username=username).first()
  File "/usr/local/lib/python3.9/site-packages/flask_sqlalchemy/model.py", line 30, in __get__
    return cls.query_class(
  File "/usr/local/lib/python3.9/site-packages/sqlalchemy/orm/query.py", line 276, in __init__
    self._set_entities(entities)
  File "/usr/local/lib/python3.9/site-packages/sqlalchemy/orm/query.py", line 288, in _set_entities
    self._raw_columns = [
  File "/usr/local/lib/python3.9/site-packages/sqlalchemy/orm/query.py", line 289, in <listcomp>
    coercions.expect(
  File "/usr/local/lib/python3.9/site-packages/sqlalchemy/sql/coercions.py", line 388, in expect
    insp._post_inspect
  File "/usr/local/lib/python3.9/site-packages/sqlalchemy/util/langhelpers.py", line 1257, in __get__
    obj.__dict__[self.__name__] = result = self.fget(obj)
  File "/usr/local/lib/python3.9/site-packages/sqlalchemy/orm/mapper.py", line 2724, in _post_inspect
    self._check_configure()
  File "/usr/local/lib/python3.9/site-packages/sqlalchemy/orm/mapper.py", line 2401, in _check_configure
    _configure_registries({self.registry}, cascade=True)
  File "/usr/local/lib/python3.9/site-packages/sqlalchemy/orm/mapper.py", line 4214, in _configure_registries
    _do_configure_registries(registries, cascade)
  File "/usr/local/lib/python3.9/site-packages/sqlalchemy/orm/mapper.py", line 4255, in _do_configure_registries
    mapper._post_configure_properties()
  File "/usr/local/lib/python3.9/site-packages/sqlalchemy/orm/mapper.py", line 2418, in _post_configure_properties
    prop.init()
  File "/usr/local/lib/python3.9/site-packages/sqlalchemy/orm/interfaces.py", line 589, in init
    self.do_init()
  File "/usr/local/lib/python3.9/site-packages/sqlalchemy/orm/relationships.py", line 1661, in do_init
    self._generate_backref()
  File "/usr/local/lib/python3.9/site-packages/sqlalchemy/orm/relationships.py", line 2147, in _generate_backref
    self._add_reverse_property(self.back_populates)
  File "/usr/local/lib/python3.9/site-packages/sqlalchemy/orm/relationships.py", line 1592, in _add_reverse_property
    other = self.mapper.get_property(key, _configure_mappers=False)
  File "/usr/local/lib/python3.9/site-packages/sqlalchemy/orm/mapper.py", line 2524, in get_property
    raise sa_exc.InvalidRequestError(
sqlalchemy.exc.InvalidRequestError: Mapper 'Mapper[User(users)]' has no property 'email_verification'.  If this property was indicated from other mappers or configure events, ensure registry.configure() has been called.
2025-04-03 10:17:23,230 - INFO - 172.28.0.9 - - [03/Apr/2025 10:17:23] "[35m[1mPOST /login HTTP/1.0[0m" 500 -
2025-04-03 10:18:01,337 - ERROR - Exception on /login [POST]
Traceback (most recent call last):
  File "/usr/local/lib/python3.9/site-packages/flask/app.py", line 2525, in wsgi_app
    response = self.full_dispatch_request()
  File "/usr/local/lib/python3.9/site-packages/flask/app.py", line 1822, in full_dispatch_request
    rv = self.handle_user_exception(e)
  File "/usr/local/lib/python3.9/site-packages/flask/app.py", line 1820, in full_dispatch_request
    rv = self.dispatch_request()
  File "/usr/local/lib/python3.9/site-packages/flask/app.py", line 1796, in dispatch_request
    return self.ensure_sync(self.view_functions[rule.endpoint])(**view_args)
  File "/app/controllers/auth_controller.py", line 46, in login
    login_response = login_user(data)
  File "/app/services/user_service.py", line 34, in login_user
    user = User.query.filter_by(username=username).first()
  File "/usr/local/lib/python3.9/site-packages/flask_sqlalchemy/model.py", line 30, in __get__
    return cls.query_class(
  File "/usr/local/lib/python3.9/site-packages/sqlalchemy/orm/query.py", line 276, in __init__
    self._set_entities(entities)
  File "/usr/local/lib/python3.9/site-packages/sqlalchemy/orm/query.py", line 288, in _set_entities
    self._raw_columns = [
  File "/usr/local/lib/python3.9/site-packages/sqlalchemy/orm/query.py", line 289, in <listcomp>
    coercions.expect(
  File "/usr/local/lib/python3.9/site-packages/sqlalchemy/sql/coercions.py", line 388, in expect
    insp._post_inspect
  File "/usr/local/lib/python3.9/site-packages/sqlalchemy/util/langhelpers.py", line 1257, in __get__
    obj.__dict__[self.__name__] = result = self.fget(obj)
  File "/usr/local/lib/python3.9/site-packages/sqlalchemy/orm/mapper.py", line 2724, in _post_inspect
    self._check_configure()
  File "/usr/local/lib/python3.9/site-packages/sqlalchemy/orm/mapper.py", line 2401, in _check_configure
    _configure_registries({self.registry}, cascade=True)
  File "/usr/local/lib/python3.9/site-packages/sqlalchemy/orm/mapper.py", line 4214, in _configure_registries
    _do_configure_registries(registries, cascade)
  File "/usr/local/lib/python3.9/site-packages/sqlalchemy/orm/mapper.py", line 4251, in _do_configure_registries
    raise e
sqlalchemy.exc.InvalidRequestError: One or more mappers failed to initialize - can't proceed with initialization of other mappers. Triggering mapper: 'Mapper[EmailVerify(email_verification)]'. Original exception was: Mapper 'Mapper[User(users)]' has no property 'email_verification'.  If this property was indicated from other mappers or configure events, ensure registry.configure() has been called.
2025-04-03 10:18:01,340 - INFO - 172.28.0.9 - - [03/Apr/2025 10:18:01] "[35m[1mPOST /login HTTP/1.0[0m" 500 -
2025-04-03 10:21:55,528 - INFO - [31m[1mWARNING: This is a development server. Do not use it in a production deployment. Use a production WSGI server instead.[0m
 * Running on all addresses (0.0.0.0)
 * Running on http://127.0.0.1:5000
 * Running on http://172.28.0.7:5000
2025-04-03 10:21:55,528 - INFO - [33mPress CTRL+C to quit[0m
2025-04-03 10:21:55,549 - INFO - [31m[1mWARNING: This is a development server. Do not use it in a production deployment. Use a production WSGI server instead.[0m
 * Running on all addresses (0.0.0.0)
 * Running on http://127.0.0.1:5000
 * Running on http://172.28.0.8:5000
2025-04-03 10:21:55,550 - INFO - [33mPress CTRL+C to quit[0m
2025-04-03 10:21:57,670 - ERROR - Exception on /login [POST]
Traceback (most recent call last):
  File "/usr/local/lib/python3.9/site-packages/sqlalchemy/orm/mapper.py", line 2522, in get_property
    return self._props[key]
KeyError: 'line_binding_user'

The above exception was the direct cause of the following exception:

Traceback (most recent call last):
  File "/usr/local/lib/python3.9/site-packages/flask/app.py", line 2525, in wsgi_app
    response = self.full_dispatch_request()
  File "/usr/local/lib/python3.9/site-packages/flask/app.py", line 1822, in full_dispatch_request
    rv = self.handle_user_exception(e)
  File "/usr/local/lib/python3.9/site-packages/flask/app.py", line 1820, in full_dispatch_request
    rv = self.dispatch_request()
  File "/usr/local/lib/python3.9/site-packages/flask/app.py", line 1796, in dispatch_request
    return self.ensure_sync(self.view_functions[rule.endpoint])(**view_args)
  File "/app/controllers/auth_controller.py", line 46, in login
    login_response = login_user(data)
  File "/app/services/user_service.py", line 34, in login_user
    user = User.query.filter_by(username=username).first()
  File "/usr/local/lib/python3.9/site-packages/flask_sqlalchemy/model.py", line 30, in __get__
    return cls.query_class(
  File "/usr/local/lib/python3.9/site-packages/sqlalchemy/orm/query.py", line 276, in __init__
    self._set_entities(entities)
  File "/usr/local/lib/python3.9/site-packages/sqlalchemy/orm/query.py", line 288, in _set_entities
    self._raw_columns = [
  File "/usr/local/lib/python3.9/site-packages/sqlalchemy/orm/query.py", line 289, in <listcomp>
    coercions.expect(
  File "/usr/local/lib/python3.9/site-packages/sqlalchemy/sql/coercions.py", line 388, in expect
    insp._post_inspect
  File "/usr/local/lib/python3.9/site-packages/sqlalchemy/util/langhelpers.py", line 1257, in __get__
    obj.__dict__[self.__name__] = result = self.fget(obj)
  File "/usr/local/lib/python3.9/site-packages/sqlalchemy/orm/mapper.py", line 2724, in _post_inspect
    self._check_configure()
  File "/usr/local/lib/python3.9/site-packages/sqlalchemy/orm/mapper.py", line 2401, in _check_configure
    _configure_registries({self.registry}, cascade=True)
  File "/usr/local/lib/python3.9/site-packages/sqlalchemy/orm/mapper.py", line 4214, in _configure_registries
    _do_configure_registries(registries, cascade)
  File "/usr/local/lib/python3.9/site-packages/sqlalchemy/orm/mapper.py", line 4255, in _do_configure_registries
    mapper._post_configure_properties()
  File "/usr/local/lib/python3.9/site-packages/sqlalchemy/orm/mapper.py", line 2418, in _post_configure_properties
    prop.init()
  File "/usr/local/lib/python3.9/site-packages/sqlalchemy/orm/interfaces.py", line 589, in init
    self.do_init()
  File "/usr/local/lib/python3.9/site-packages/sqlalchemy/orm/relationships.py", line 1661, in do_init
    self._generate_backref()
  File "/usr/local/lib/python3.9/site-packages/sqlalchemy/orm/relationships.py", line 2147, in _generate_backref
    self._add_reverse_property(self.back_populates)
  File "/usr/local/lib/python3.9/site-packages/sqlalchemy/orm/relationships.py", line 1592, in _add_reverse_property
    other = self.mapper.get_property(key, _configure_mappers=False)
  File "/usr/local/lib/python3.9/site-packages/sqlalchemy/orm/mapper.py", line 2524, in get_property
    raise sa_exc.InvalidRequestError(
sqlalchemy.exc.InvalidRequestError: Mapper 'Mapper[User(users)]' has no property 'line_binding_user'.  If this property was indicated from other mappers or configure events, ensure registry.configure() has been called.
2025-04-03 10:21:57,680 - INFO - 172.28.0.9 - - [03/Apr/2025 10:21:57] "[35m[1mPOST /login HTTP/1.0[0m" 500 -
2025-04-03 10:22:04,147 - ERROR - Exception on /login [POST]
Traceback (most recent call last):
  File "/usr/local/lib/python3.9/site-packages/sqlalchemy/orm/mapper.py", line 2522, in get_property
    return self._props[key]
KeyError: 'line_binding_user'

The above exception was the direct cause of the following exception:

Traceback (most recent call last):
  File "/usr/local/lib/python3.9/site-packages/flask/app.py", line 2525, in wsgi_app
    response = self.full_dispatch_request()
  File "/usr/local/lib/python3.9/site-packages/flask/app.py", line 1822, in full_dispatch_request
    rv = self.handle_user_exception(e)
  File "/usr/local/lib/python3.9/site-packages/flask/app.py", line 1820, in full_dispatch_request
    rv = self.dispatch_request()
  File "/usr/local/lib/python3.9/site-packages/flask/app.py", line 1796, in dispatch_request
    return self.ensure_sync(self.view_functions[rule.endpoint])(**view_args)
  File "/app/controllers/auth_controller.py", line 46, in login
    login_response = login_user(data)
  File "/app/services/user_service.py", line 34, in login_user
    user = User.query.filter_by(username=username).first()
  File "/usr/local/lib/python3.9/site-packages/flask_sqlalchemy/model.py", line 30, in __get__
    return cls.query_class(
  File "/usr/local/lib/python3.9/site-packages/sqlalchemy/orm/query.py", line 276, in __init__
    self._set_entities(entities)
  File "/usr/local/lib/python3.9/site-packages/sqlalchemy/orm/query.py", line 288, in _set_entities
    self._raw_columns = [
  File "/usr/local/lib/python3.9/site-packages/sqlalchemy/orm/query.py", line 289, in <listcomp>
    coercions.expect(
  File "/usr/local/lib/python3.9/site-packages/sqlalchemy/sql/coercions.py", line 388, in expect
    insp._post_inspect
  File "/usr/local/lib/python3.9/site-packages/sqlalchemy/util/langhelpers.py", line 1257, in __get__
    obj.__dict__[self.__name__] = result = self.fget(obj)
  File "/usr/local/lib/python3.9/site-packages/sqlalchemy/orm/mapper.py", line 2724, in _post_inspect
    self._check_configure()
  File "/usr/local/lib/python3.9/site-packages/sqlalchemy/orm/mapper.py", line 2401, in _check_configure
    _configure_registries({self.registry}, cascade=True)
  File "/usr/local/lib/python3.9/site-packages/sqlalchemy/orm/mapper.py", line 4214, in _configure_registries
    _do_configure_registries(registries, cascade)
  File "/usr/local/lib/python3.9/site-packages/sqlalchemy/orm/mapper.py", line 4255, in _do_configure_registries
    mapper._post_configure_properties()
  File "/usr/local/lib/python3.9/site-packages/sqlalchemy/orm/mapper.py", line 2418, in _post_configure_properties
    prop.init()
  File "/usr/local/lib/python3.9/site-packages/sqlalchemy/orm/interfaces.py", line 589, in init
    self.do_init()
  File "/usr/local/lib/python3.9/site-packages/sqlalchemy/orm/relationships.py", line 1661, in do_init
    self._generate_backref()
  File "/usr/local/lib/python3.9/site-packages/sqlalchemy/orm/relationships.py", line 2147, in _generate_backref
    self._add_reverse_property(self.back_populates)
  File "/usr/local/lib/python3.9/site-packages/sqlalchemy/orm/relationships.py", line 1592, in _add_reverse_property
    other = self.mapper.get_property(key, _configure_mappers=False)
  File "/usr/local/lib/python3.9/site-packages/sqlalchemy/orm/mapper.py", line 2524, in get_property
    raise sa_exc.InvalidRequestError(
sqlalchemy.exc.InvalidRequestError: Mapper 'Mapper[User(users)]' has no property 'line_binding_user'.  If this property was indicated from other mappers or configure events, ensure registry.configure() has been called.
2025-04-03 10:22:04,157 - INFO - 172.28.0.9 - - [03/Apr/2025 10:22:04] "[35m[1mPOST /login HTTP/1.0[0m" 500 -
2025-04-03 10:22:11,809 - ERROR - Exception on /login [POST]
Traceback (most recent call last):
  File "/usr/local/lib/python3.9/site-packages/flask/app.py", line 2525, in wsgi_app
    response = self.full_dispatch_request()
  File "/usr/local/lib/python3.9/site-packages/flask/app.py", line 1822, in full_dispatch_request
    rv = self.handle_user_exception(e)
  File "/usr/local/lib/python3.9/site-packages/flask/app.py", line 1820, in full_dispatch_request
    rv = self.dispatch_request()
  File "/usr/local/lib/python3.9/site-packages/flask/app.py", line 1796, in dispatch_request
    return self.ensure_sync(self.view_functions[rule.endpoint])(**view_args)
  File "/app/controllers/auth_controller.py", line 46, in login
    login_response = login_user(data)
  File "/app/services/user_service.py", line 34, in login_user
    user = User.query.filter_by(username=username).first()
  File "/usr/local/lib/python3.9/site-packages/flask_sqlalchemy/model.py", line 30, in __get__
    return cls.query_class(
  File "/usr/local/lib/python3.9/site-packages/sqlalchemy/orm/query.py", line 276, in __init__
    self._set_entities(entities)
  File "/usr/local/lib/python3.9/site-packages/sqlalchemy/orm/query.py", line 288, in _set_entities
    self._raw_columns = [
  File "/usr/local/lib/python3.9/site-packages/sqlalchemy/orm/query.py", line 289, in <listcomp>
    coercions.expect(
  File "/usr/local/lib/python3.9/site-packages/sqlalchemy/sql/coercions.py", line 388, in expect
    insp._post_inspect
  File "/usr/local/lib/python3.9/site-packages/sqlalchemy/util/langhelpers.py", line 1257, in __get__
    obj.__dict__[self.__name__] = result = self.fget(obj)
  File "/usr/local/lib/python3.9/site-packages/sqlalchemy/orm/mapper.py", line 2724, in _post_inspect
    self._check_configure()
  File "/usr/local/lib/python3.9/site-packages/sqlalchemy/orm/mapper.py", line 2401, in _check_configure
    _configure_registries({self.registry}, cascade=True)
  File "/usr/local/lib/python3.9/site-packages/sqlalchemy/orm/mapper.py", line 4214, in _configure_registries
    _do_configure_registries(registries, cascade)
  File "/usr/local/lib/python3.9/site-packages/sqlalchemy/orm/mapper.py", line 4251, in _do_configure_registries
    raise e
sqlalchemy.exc.InvalidRequestError: One or more mappers failed to initialize - can't proceed with initialization of other mappers. Triggering mapper: 'Mapper[LineBindingUser(line_binding_user)]'. Original exception was: Mapper 'Mapper[User(users)]' has no property 'line_binding_user'.  If this property was indicated from other mappers or configure events, ensure registry.configure() has been called.
2025-04-03 10:22:11,810 - INFO - 172.28.0.9 - - [03/Apr/2025 10:22:11] "[35m[1mPOST /login HTTP/1.0[0m" 500 -
2025-04-03 10:22:12,900 - ERROR - Exception on /login [POST]
Traceback (most recent call last):
  File "/usr/local/lib/python3.9/site-packages/flask/app.py", line 2525, in wsgi_app
    response = self.full_dispatch_request()
  File "/usr/local/lib/python3.9/site-packages/flask/app.py", line 1822, in full_dispatch_request
    rv = self.handle_user_exception(e)
  File "/usr/local/lib/python3.9/site-packages/flask/app.py", line 1820, in full_dispatch_request
    rv = self.dispatch_request()
  File "/usr/local/lib/python3.9/site-packages/flask/app.py", line 1796, in dispatch_request
    return self.ensure_sync(self.view_functions[rule.endpoint])(**view_args)
  File "/app/controllers/auth_controller.py", line 46, in login
    login_response = login_user(data)
  File "/app/services/user_service.py", line 34, in login_user
    user = User.query.filter_by(username=username).first()
  File "/usr/local/lib/python3.9/site-packages/flask_sqlalchemy/model.py", line 30, in __get__
    return cls.query_class(
  File "/usr/local/lib/python3.9/site-packages/sqlalchemy/orm/query.py", line 276, in __init__
    self._set_entities(entities)
  File "/usr/local/lib/python3.9/site-packages/sqlalchemy/orm/query.py", line 288, in _set_entities
    self._raw_columns = [
  File "/usr/local/lib/python3.9/site-packages/sqlalchemy/orm/query.py", line 289, in <listcomp>
    coercions.expect(
  File "/usr/local/lib/python3.9/site-packages/sqlalchemy/sql/coercions.py", line 388, in expect
    insp._post_inspect
  File "/usr/local/lib/python3.9/site-packages/sqlalchemy/util/langhelpers.py", line 1257, in __get__
    obj.__dict__[self.__name__] = result = self.fget(obj)
  File "/usr/local/lib/python3.9/site-packages/sqlalchemy/orm/mapper.py", line 2724, in _post_inspect
    self._check_configure()
  File "/usr/local/lib/python3.9/site-packages/sqlalchemy/orm/mapper.py", line 2401, in _check_configure
    _configure_registries({self.registry}, cascade=True)
  File "/usr/local/lib/python3.9/site-packages/sqlalchemy/orm/mapper.py", line 4214, in _configure_registries
    _do_configure_registries(registries, cascade)
  File "/usr/local/lib/python3.9/site-packages/sqlalchemy/orm/mapper.py", line 4251, in _do_configure_registries
    raise e
sqlalchemy.exc.InvalidRequestError: One or more mappers failed to initialize - can't proceed with initialization of other mappers. Triggering mapper: 'Mapper[LineBindingUser(line_binding_user)]'. Original exception was: Mapper 'Mapper[User(users)]' has no property 'line_binding_user'.  If this property was indicated from other mappers or configure events, ensure registry.configure() has been called.
2025-04-03 10:22:12,902 - INFO - 172.28.0.9 - - [03/Apr/2025 10:22:12] "[35m[1mPOST /login HTTP/1.0[0m" 500 -
2025-04-03 10:22:13,395 - ERROR - Exception on /login [POST]
Traceback (most recent call last):
  File "/usr/local/lib/python3.9/site-packages/flask/app.py", line 2525, in wsgi_app
    response = self.full_dispatch_request()
  File "/usr/local/lib/python3.9/site-packages/flask/app.py", line 1822, in full_dispatch_request
    rv = self.handle_user_exception(e)
  File "/usr/local/lib/python3.9/site-packages/flask/app.py", line 1820, in full_dispatch_request
    rv = self.dispatch_request()
  File "/usr/local/lib/python3.9/site-packages/flask/app.py", line 1796, in dispatch_request
    return self.ensure_sync(self.view_functions[rule.endpoint])(**view_args)
  File "/app/controllers/auth_controller.py", line 46, in login
    login_response = login_user(data)
  File "/app/services/user_service.py", line 34, in login_user
    user = User.query.filter_by(username=username).first()
  File "/usr/local/lib/python3.9/site-packages/flask_sqlalchemy/model.py", line 30, in __get__
    return cls.query_class(
  File "/usr/local/lib/python3.9/site-packages/sqlalchemy/orm/query.py", line 276, in __init__
    self._set_entities(entities)
  File "/usr/local/lib/python3.9/site-packages/sqlalchemy/orm/query.py", line 288, in _set_entities
    self._raw_columns = [
  File "/usr/local/lib/python3.9/site-packages/sqlalchemy/orm/query.py", line 289, in <listcomp>
    coercions.expect(
  File "/usr/local/lib/python3.9/site-packages/sqlalchemy/sql/coercions.py", line 388, in expect
    insp._post_inspect
  File "/usr/local/lib/python3.9/site-packages/sqlalchemy/util/langhelpers.py", line 1257, in __get__
    obj.__dict__[self.__name__] = result = self.fget(obj)
  File "/usr/local/lib/python3.9/site-packages/sqlalchemy/orm/mapper.py", line 2724, in _post_inspect
    self._check_configure()
  File "/usr/local/lib/python3.9/site-packages/sqlalchemy/orm/mapper.py", line 2401, in _check_configure
    _configure_registries({self.registry}, cascade=True)
  File "/usr/local/lib/python3.9/site-packages/sqlalchemy/orm/mapper.py", line 4214, in _configure_registries
    _do_configure_registries(registries, cascade)
  File "/usr/local/lib/python3.9/site-packages/sqlalchemy/orm/mapper.py", line 4251, in _do_configure_registries
    raise e
sqlalchemy.exc.InvalidRequestError: One or more mappers failed to initialize - can't proceed with initialization of other mappers. Triggering mapper: 'Mapper[LineBindingUser(line_binding_user)]'. Original exception was: Mapper 'Mapper[User(users)]' has no property 'line_binding_user'.  If this property was indicated from other mappers or configure events, ensure registry.configure() has been called.
2025-04-03 10:22:13,396 - INFO - 172.28.0.9 - - [03/Apr/2025 10:22:13] "[35m[1mPOST /login HTTP/1.0[0m" 500 -
2025-04-03 10:23:39,830 - INFO - [31m[1mWARNING: This is a development server. Do not use it in a production deployment. Use a production WSGI server instead.[0m
 * Running on all addresses (0.0.0.0)
 * Running on http://127.0.0.1:5000
 * Running on http://172.28.0.7:5000
2025-04-03 10:23:39,831 - INFO - [33mPress CTRL+C to quit[0m
2025-04-03 10:23:39,888 - INFO - [31m[1mWARNING: This is a development server. Do not use it in a production deployment. Use a production WSGI server instead.[0m
 * Running on all addresses (0.0.0.0)
 * Running on http://127.0.0.1:5000
 * Running on http://172.28.0.8:5000
2025-04-03 10:23:39,889 - INFO - [33mPress CTRL+C to quit[0m
2025-04-03 10:23:44,779 - INFO - 172.28.0.9 - - [03/Apr/2025 10:23:44] "POST /login HTTP/1.0" 200 -
2025-04-03 10:23:44,858 - INFO - 172.28.0.9 - - [03/Apr/2025 10:23:44] "GET /users HTTP/1.0" 200 -
2025-04-03 10:23:44,874 - INFO - 172.28.0.9 - - [03/Apr/2025 10:23:44] "GET /get_user_image HTTP/1.0" 200 -
